Workbook

Sheet PROYECTADA
R1: =R2*8 -> 216 | S1: Horas | Y1: FDM
R2: 27 | S2: Dias laborables
R3: 31 | S3: Dias | AF3: BONIFICACIÓN ENERO 2026
A4: MES DE ENERO 2026 | X4: SISTEMA MES DE ENERO 2026
A5: Nº | B5: NOMBRES | C5: SPP o SNP | D5: SUELDO BRUTO | H5: SUELDO BRUTO | I5: DSCTO. A.F.P.(Prima de Seguro | J5: SUELDO NETO | K5: BENEFICIOS SOCIALES PROYECTADOS | O5: APORTES DEL EMPLEADOR | S5: SUELDO NETO + BENF. SOCI. PROYEC. | T5: SUELDO BRUTO + BENF. SOCI. PROYEC. + APORT. EMPLE. | U5: JORNAL DIARIO | V5: COSTO HORA | X5: Nº | Y5: NOMBRES | Z5: DIFERENCIA O BONIFICACION | AA5: SUELDO NETO TOTAL | AB5: SUELDO BRUTO NEGRO | AC5: SUELDO POR DIA | AD5: SUELDO POR HORA | AF5: Diferencia por h. | AG5: Diferencia real
D6: REMUNERACIÓN BÁSICA | E6: BONIF. | F6: ASIGNACION FAMILIAR | G6: COMPEN. | K6: CTS | L6: GRATIFICACIONES | M6: ESSALUD GRATIFICACIONES | N6: BETA 30 % | O6: ESSALUD | P6: VIDA LEY | Q6: PENSION SCTR | R6: ESSALUD EPS | AI6: Diferencia real de personas en vacaciones
A7: 1 | B7: Apaza Tito Patricia | C7: PRO F | D7: =37.6666666666667*$R$3 -> 1167.6667 | E7: 125 | H7: =SUM(D7:G7) -> 1292.6667 | I7: =H7*$D$66 -> 168.82227 | J7: =H7-I7 -> 1123.8444 | K7: =((D7+E7+F7)*(9.72%)) -> 125.6472 | L7: =(D7+E7+F7)*(16.66%) -> 215.35827 | M7: =L7*6% -> 12.921496 | N7: =(1130*30%)/(30)*30 -> 339 | O7: =H7*6% -> 77.56 | P7: =((H7*(0.63%))*1.18) -> 9.609684 | Q7: =(H7*(0.57%))*1.18 -> 8.694476 | R7: =(H7*(0.55%))*1.18 -> 8.3894067 | S7: =J7+K7+L7+M7+N7 -> 1816.7714 | T7: =H7+K7+L7+M7+N7+O7+P7+Q7+R7 -> 2089.8472 | U7: =T7/$R$2 -> 77.401748 | V7: =+U7/8 -> 9.6752185 | X7: =A7 -> 1 | Y7: =B7 -> Apaza Tito Patricia | Z7: =AA7-S7 -> 708.22864 | AA7: =2400+125 -> 2525 | AB7: =T7+Z7 -> 2798.0758 | AC7: =AB7/$R$2 -> 103.63244 | AD7: =+AC7/8 -> 12.954055 | AF7: =Z7/$R$1 -> 3.2788363
A8: 2 | B8: Aquino Gómez Basilia Isabel | C8: PRO F | D8: =37.6666666666667*$R$3 -> 1167.6667 | H8: =SUM(D8:G8) -> 1167.6667 | I8: =H8*$D$66 -> 152.49727 | J8: =H8-I8 -> 1015.1694 | K8: =((D8+E8+F8)*(9.72%)) -> 113.4972 | L8: =(D8+E8+F8)*(16.66%) -> 194.53327 | M8: =L8*6% -> 11.671996 | N8: =(1130*30%)/(30)*30 -> 339 | O8: =H8*6% -> 70.06 | P8: =((H8*(0.63%))*1.18) -> 8.680434 | Q8: =(H8*(0.57%))*1.18 -> 7.853726 | R8: =(H8*(0.55%))*1.18 -> 7.5781567 | S8: =J8+K8+L8+M8+N8 -> 1673.8719 | T8: =H8+K8+L8+M8+N8+O8+P8+Q8+R8 -> 1920.5414 | U8: =T8/$R$2 -> 71.131165 | V8: =+U8/8 -> 8.8913956 | X8: =A8 -> 2 | Y8: =B8 -> Aquino Gómez Basilia Isabel | Z8: =AA8-S8 -> 326.12814 | AA8: =1775+100+125 -> 2000 | AB8: =T8+Z8 -> 2246.6696 | AC8: =AB8/$R$2 -> 83.209985 | AD8: =+AC8/8 -> 10.401248 | AF8: =Z8/$R$1 -> 1.5098525
A9: 3 | B9: Calla G Guillermina | C9: PRO F | D9: =37.6666666666667*$R$3 -> 1167.6667 | H9: =SUM(D9:G9) -> 1167.6667 | I9: =H9*$D$66 -> 152.49727 | J9: =H9-I9 -> 1015.1694 | K9: =((D9+E9+F9)*(9.72%)) -> 113.4972 | L9: =(D9+E9+F9)*(16.66%) -> 194.53327 | M9: =L9*6% -> 11.671996 | N9: =(1130*30%)/(30)*30 -> 339 | O9: =H9*6% -> 70.06 | P9: =((H9*(0.63%))*1.18) -> 8.680434 | Q9: =(H9*(0.57%))*1.18 -> 7.853726 | R9: =(H9*(0.55%))*1.18 -> 7.5781567 | S9: =J9+K9+L9+M9+N9 -> 1673.8719 | T9: =H9+K9+L9+M9+N9+O9+P9+Q9+R9 -> 1920.5414 | U9: =T9/$R$2 -> 71.131165 | V9: =+U9/8 -> 8.8913956 | X9: =A9 -> 3 | Y9: =B9 -> Calla G Guillermina | Z9: =AA9-S9 -> 326.12814 | AA9: =1775+100+125 -> 2000 | AB9: =T9+Z9 -> 2246.6696 | AC9: =AB9/$R$2 -> 83.209985 | AD9: =+AC9/8 -> 10.401248 | AF9: =Z9/$R$1 -> 1.5098525
A10: 4 | B10: Challco Laime, Gilberta | C10: HAB M | D10: =37.6666666666667*$R$3 -> 1167.6667 | H10: =SUM(D10:G10) -> 1167.6667 | I10: =H10*$E$68 -> 132.7637 | J10: =H10-I10 -> 1034.903 | K10: =((D10+E10+F10)*(9.72%)) -> 113.4972 | L10: =(D10+E10+F10)*(16.66%) -> 194.53327 | M10: =L10*6% -> 11.671996 | N10: =(1130*30%)/(30)*30 -> 339 | O10: =H10*6% -> 70.06 | P10: =((H10*(0.63%))*1.18) -> 8.680434 | Q10: =(H10*(0.57%))*1.18 -> 7.853726 | R10: =(H10*(0.55%))*1.18 -> 7.5781567 | S10: =J10+K10+L10+M10+N10 -> 1693.6054 | T10: =H10+K10+L10+M10+N10+O10+P10+Q10+R10 -> 1920.5414 | U10: =T10/$R$2 -> 71.131165 | V10: =+U10/8 -> 8.8913956 | X10: =A10 -> 4 | Y10: =B10 -> Challco Laime, Gilberta | Z10: =AA10-S10 -> 306.39457 | AA10: =1775+100+125 -> 2000 | AB10: =T10+Z10 -> 2226.936 | AC10: =AB10/$R$2 -> 82.479112 | AD10: =+AC10/8 -> 10.309889 | AF10: =Z10/$R$1 -> 1.4184934
A11: 5 | B11: Choquehuayta Huallpa, Estefania | C11: PRO M | D11: =37.6666666666667*$R$3 -> 1167.6667 | F11: 113 | H11: =SUM(D11:G11) -> 1280.6667 | I11: =H11*$E$70 -> 145.6118 | J11: =H11-I11 -> 1135.0549 | K11: =((D11+E11+F11)*(9.72%)) -> 124.4808 | L11: =(D11+E11+F11)*(16.66%) -> 213.35907 | M11: =L11*6% -> 12.801544 | N11: =(1130*30%)/(30)*30 -> 339 | O11: =H11*6% -> 76.84 | P11: =((H11*(0.63%))*1.18) -> 9.520476 | Q11: =(H11*(0.57%))*1.18 -> 8.613764 | R11: =(H11*(0.55%))*1.18 -> 8.3115267 | S11: =J11+K11+L11+M11+N11 -> 1824.6963 | T11: =H11+K11+L11+M11+N11+O11+P11+Q11+R11 -> 2073.5938 | U11: =T11/$R$2 -> 76.799772 | V11: =+U11/8 -> 9.5999715 | X11: =A11 -> 5 | Y11: =B11 -> Choquehuayta Huallpa, Estefania | Z11: =AA11-S11 -> 175.30372 | AA11: =1775+100+125 -> 2000 | AB11: =T11+Z11 -> 2248.8976 | AC11: =AB11/$R$2 -> 83.292502 | AD11: =+AC11/8 -> 10.411563 | AF11: =Z11/$R$1 -> 0.81159131
A12: 6 | B12: Idme Huaraccallo, Gladis | C12: SNP | D12: =37.6666666666667*$R$3 -> 1167.6667 | H12: =SUM(D12:G12) -> 1167.6667 | I12: =H12*$E$69 -> 151.79667 | J12: =H12-I12 -> 1015.87 | K12: =((D12+E12+F12)*(9.72%)) -> 113.4972 | L12: =(D12+E12+F12)*(16.66%) -> 194.53327 | M12: =L12*6% -> 11.671996 | N12: =(1130*30%)/(30)*30 -> 339 | O12: =H12*6% -> 70.06 | P12: =((H12*(0.63%))*1.18) -> 8.680434 | Q12: =(H12*(0.57%))*1.18 -> 7.853726 | R12: =(H12*(0.55%))*1.18 -> 7.5781567 | S12: =J12+K12+L12+M12+N12 -> 1674.5725 | T12: =H12+K12+L12+M12+N12+O12+P12+Q12+R12 -> 1920.5414 | U12: =T12/$R$2 -> 71.131165 | V12: =+U12/8 -> 8.8913956 | X12: =A12 -> 6 | Y12: =B12 -> Idme Huaraccallo, Gladis | Z12: =AA12-S12 -> 325.42754 | AA12: =1775+100+125 -> 2000 | AB12: =T12+Z12 -> 2245.969 | AC12: =AB12/$R$2 -> 83.184036 | AD12: =+AC12/8 -> 10.398005 | AF12: =Z12/$R$1 -> 1.506609
A13: 7 | B13: Jacha Gomez, Flavia | C13: INT F | D13: =37.6666666666667*$R$3 -> 1167.6667 | H13: =SUM(D13:G13) -> 1167.6667 | I13: =H13*$D$64 -> 150.86253 | J13: =H13-I13 -> 1016.8041 | K13: =((D13+E13+F13)*(9.72%)) -> 113.4972 | L13: =(D13+E13+F13)*(16.66%) -> 194.53327 | M13: =L13*6% -> 11.671996 | N13: =(1130*30%)/(30)*30 -> 339 | O13: =H13*6% -> 70.06 | P13: =((H13*(0.63%))*1.18) -> 8.680434 | Q13: =(H13*(0.57%))*1.18 -> 7.853726 | R13: =(H13*(0.55%))*1.18 -> 7.5781567 | S13: =J13+K13+L13+M13+N13 -> 1675.5066 | T13: =H13+K13+L13+M13+N13+O13+P13+Q13+R13 -> 1920.5414 | U13: =T13/$R$2 -> 71.131165 | V13: =+U13/8 -> 8.8913956 | X13: =A13 -> 7 | Y13: =B13 -> Jacha Gomez, Flavia | Z13: =AA13-S13 -> 474.4934 | AA13: =1925+100+125 -> 2150 | AB13: =T13+Z13 -> 2395.0349 | AC13: =AB13/$R$2 -> 88.704994 | AD13: =+AC13/8 -> 11.088124 | AF13: =Z13/$R$1 -> 2.1967287
A14: 8 | B14: Lerma Yanarico Elena | C14: PRO F | D14: =37.6666666666667*$R$3 -> 1167.6667 | F14: 113 | H14: =SUM(D14:G14) -> 1280.6667 | I14: =H14*$D$66 -> 167.25507 | J14: =H14-I14 -> 1113.4116 | K14: =((D14+E14+F14)*(9.72%)) -> 124.4808 | L14: =(D14+E14+F14)*(16.66%) -> 213.35907 | M14: =L14*6% -> 12.801544 | N14: =(1130*30%)/(30)*30 -> 339 | O14: =H14*6% -> 76.84 | P14: =((H14*(0.63%))*1.18) -> 9.520476 | Q14: =(H14*(0.57%))*1.18 -> 8.613764 | R14: =(H14*(0.55%))*1.18 -> 8.3115267 | S14: =J14+K14+L14+M14+N14 -> 1803.053 | T14: =H14+K14+L14+M14+N14+O14+P14+Q14+R14 -> 2073.5938 | U14: =T14/$R$2 -> 76.799772 | V14: =+U14/8 -> 9.5999715 | X14: =A14 -> 8 | Y14: =B14 -> Lerma Yanarico Elena | Z14: =AA14-S14 -> 196.94699 | AA14: =1775+100+125 -> 2000 | AB14: =T14+Z14 -> 2270.5408 | AC14: =AB14/$R$2 -> 84.094105 | AD14: =+AC14/8 -> 10.511763 | AF14: =Z14/$R$1 -> 0.91179162
A15: 9 | B15: Machaca Calcina, Benedicta | C15: INT M | D15: =37.6666666666667*$R$3 -> 1167.6667 | F15: 113 | H15: =SUM(D15:G15) -> 1280.6667 | I15: =H15*$E$71 -> 145.6118 | J15: =H15-I15 -> 1135.0549 | K15: =((D15+E15+F15)*(9.72%)) -> 124.4808 | L15: =(D15+E15+F15)*(16.66%) -> 213.35907 | M15: =L15*6% -> 12.801544 | N15: =(1130*30%)/(30)*30 -> 339 | O15: =H15*6% -> 76.84 | P15: =((H15*(0.63%))*1.18) -> 9.520476 | Q15: =(H15*(0.57%))*1.18 -> 8.613764 | R15: =(H15*(0.55%))*1.18 -> 8.3115267 | S15: =J15+K15+L15+M15+N15 -> 1824.6963 | T15: =H15+K15+L15+M15+N15+O15+P15+Q15+R15 -> 2073.5938 | U15: =T15/$R$2 -> 76.799772 | V15: =+U15/8 -> 9.5999715 | X15: =A15 -> 9 | Y15: =B15 -> Machaca Calcina, Benedicta | Z15: =AA15-S15 -> 175.30372 | AA15: =1775+100+125 -> 2000 | AB15: =T15+Z15 -> 2248.8976 | AC15: =AB15/$R$2 -> 83.292502 | AD15: =+AC15/8 -> 10.411563 | AF15: =Z15/$R$1 -> 0.81159131
A16: 10 | B16: Mamani Hancco, Elsa Teresa | C16: INT F | D16: =37.6666666666667*$R$3 -> 1167.6667 | F16: 113 | H16: =SUM(D16:G16) -> 1280.6667 | I16: =H16*$D$64 -> 165.46213 | J16: =H16-I16 -> 1115.2045 | K16: =((D16+E16+F16)*(9.72%)) -> 124.4808 | L16: =(D16+E16+F16)*(16.66%) -> 213.35907 | M16: =L16*6% -> 12.801544 | N16: =(1130*30%)/(30)*30 -> 339 | O16: =H16*6% -> 76.84 | P16: =((H16*(0.63%))*1.18) -> 9.520476 | Q16: =(H16*(0.57%))*1.18 -> 8.613764 | R16: =(H16*(0.55%))*1.18 -> 8.3115267 | S16: =J16+K16+L16+M16+N16 -> 1804.8459 | T16: =H16+K16+L16+M16+N16+O16+P16+Q16+R16 -> 2073.5938 | U16: =T16/$R$2 -> 76.799772 | V16: =+U16/8 -> 9.5999715 | X16: =A16 -> 10 | Y16: =B16 -> Mamani Hancco, Elsa Teresa | Z16: =AA16-S16 -> 195.15406 | AA16: =1775+100+125 -> 2000 | AB16: =T16+Z16 -> 2268.7479 | AC16: =AB16/$R$2 -> 84.0277 | AD16: =+AC16/8 -> 10.503463 | AF16: =Z16/$R$1 -> 0.903491
A17: 11 | B17: Mamani Itusaca de Perca Guzmila | C17: HAB M | D17: =37.6666666666667*$R$3 -> 1167.6667 | H17: =SUM(D17:G17) -> 1167.6667 | I17: =H17*$E$68 -> 132.7637 | J17: =H17-I17 -> 1034.903 | K17: =((D17+E17+F17)*(9.72%)) -> 113.4972 | L17: =(D17+E17+F17)*(16.66%) -> 194.53327 | M17: =L17*6% -> 11.671996 | N17: =(1130*30%)/(30)*30 -> 339 | O17: =H17*6% -> 70.06 | P17: =((H17*(0.63%))*1.18) -> 8.680434 | Q17: =(H17*(0.57%))*1.18 -> 7.853726 | R17: =(H17*(0.55%))*1.18 -> 7.5781567 | S17: =J17+K17+L17+M17+N17 -> 1693.6054 | T17: =H17+K17+L17+M17+N17+O17+P17+Q17+R17 -> 1920.5414 | U17: =T17/$R$2 -> 71.131165 | V17: =+U17/8 -> 8.8913956 | X17: =A17 -> 11 | Y17: =B17 -> Mamani Itusaca de Perca Guzmila | Z17: =AA17-S17 -> 306.39457 | AA17: =1775+100+125 -> 2000 | AB17: =T17+Z17 -> 2226.936 | AC17: =AB17/$R$2 -> 82.479112 | AD17: =+AC17/8 -> 10.309889 | AF17: =Z17/$R$1 -> 1.4184934
A18: 12 | B18: Mayta Coaquira Janet Venancia | C18: INT M | D18: =37.6666666666667*$R$3 -> 1167.6667 | H18: =SUM(D18:G18) -> 1167.6667 | I18: =H18*$E$71 -> 132.7637 | J18: =H18-I18 -> 1034.903 | K18: =((D18+E18+F18)*(9.72%)) -> 113.4972 | L18: =(D18+E18+F18)*(16.66%) -> 194.53327 | M18: =L18*6% -> 11.671996 | N18: =(1130*30%)/(30)*30 -> 339 | O18: =H18*6% -> 70.06 | P18: =((H18*(0.63%))*1.18) -> 8.680434 | Q18: =(H18*(0.57%))*1.18 -> 7.853726 | R18: =(H18*(0.55%))*1.18 -> 7.5781567 | S18: =J18+K18+L18+M18+N18 -> 1693.6054 | T18: =H18+K18+L18+M18+N18+O18+P18+Q18+R18 -> 1920.5414 | U18: =T18/$R$2 -> 71.131165 | V18: =+U18/8 -> 8.8913956 | X18: =A18 -> 12 | Y18: =B18 -> Mayta Coaquira Janet Venancia | Z18: =AA18-S18 -> 306.39457 | AA18: =1775+100+125 -> 2000 | AB18: =T18+Z18 -> 2226.936 | AC18: =AB18/$R$2 -> 82.479112 | AD18: =+AC18/8 -> 10.309889 | AF18: =Z18/$R$1 -> 1.4184934
A19: 13 | B19: Parari Laura Teresa Lucy | C19: PRO M | D19: =37.6666666666667*$R$3 -> 1167.6667 | H19: =SUM(D19:G19) -> 1167.6667 | I19: =H19*$E$70 -> 132.7637 | J19: =H19-I19 -> 1034.903 | K19: =((D19+E19+F19)*(9.72%)) -> 113.4972 | L19: =(D19+E19+F19)*(16.66%) -> 194.53327 | M19: =L19*6% -> 11.671996 | N19: =(1130*30%)/(30)*30 -> 339 | O19: =H19*6% -> 70.06 | P19: =((H19*(0.63%))*1.18) -> 8.680434 | Q19: =(H19*(0.57%))*1.18 -> 7.853726 | R19: =(H19*(0.55%))*1.18 -> 7.5781567 | S19: =J19+K19+L19+M19+N19 -> 1693.6054 | T19: =H19+K19+L19+M19+N19+O19+P19+Q19+R19 -> 1920.5414 | U19: =T19/$R$2 -> 71.131165 | V19: =+U19/8 -> 8.8913956 | X19: =A19 -> 13 | Y19: =B19 -> Parari Laura Teresa Lucy | Z19: =AA19-S19 -> 306.39457 | AA19: =1775+100+125 -> 2000 | AB19: =T19+Z19 -> 2226.936 | AC19: =AB19/$R$2 -> 82.479112 | AD19: =+AC19/8 -> 10.309889 | AF19: =Z19/$R$1 -> 1.4184934
A20: 14 | B20: Pelinco Machaca, Monica | C20: PRI M | D20: =37.6666666666667*$R$3 -> 1167.6667 | H20: =SUM(D20:G20) -> 1167.6667 | I20: =H20*$E$72 -> 132.7637 | J20: =H20-I20 -> 1034.903 | K20: =((D20+E20+F20)*(9.72%)) -> 113.4972 | L20: =(D20+E20+F20)*(16.66%) -> 194.53327 | M20: =L20*6% -> 11.671996 | N20: =(1130*30%)/(30)*30 -> 339 | O20: =H20*6% -> 70.06 | P20: =((H20*(0.63%))*1.18) -> 8.680434 | Q20: =(H20*(0.57%))*1.18 -> 7.853726 | R20: =(H20*(0.55%))*1.18 -> 7.5781567 | S20: =J20+K20+L20+M20+N20 -> 1693.6054 | T20: =H20+K20+L20+M20+N20+O20+P20+Q20+R20 -> 1920.5414 | U20: =T20/$R$2 -> 71.131165 | V20: =+U20/8 -> 8.8913956 | X20: =A20 -> 14 | Y20: =B20 -> Pelinco Machaca, Monica | Z20: =AA20-S20 -> 306.39457 | AA20: =1775+100+125 -> 2000 | AB20: =T20+Z20 -> 2226.936 | AC20: =AB20/$R$2 -> 82.479112 | AD20: =+AC20/8 -> 10.309889 | AF20: =Z20/$R$1 -> 1.4184934
A21: 15 | B21: Quispe Pacco Obita | C21: PRO F | D21: =37.6666666666667*$R$3 -> 1167.6667 | H21: =SUM(D21:G21) -> 1167.6667 | I21: =H21*$D$66 -> 152.49727 | J21: =H21-I21 -> 1015.1694 | K21: =((D21+E21+F21)*(9.72%)) -> 113.4972 | L21: =(D21+E21+F21)*(16.66%) -> 194.53327 | M21: =L21*6% -> 11.671996 | N21: =(1130*30%)/(30)*30 -> 339 | O21: =H21*6% -> 70.06 | P21: =((H21*(0.63%))*1.18) -> 8.680434 | Q21: =(H21*(0.57%))*1.18 -> 7.853726 | R21: =(H21*(0.55%))*1.18 -> 7.5781567 | S21: =J21+K21+L21+M21+N21 -> 1673.8719 | T21: =H21+K21+L21+M21+N21+O21+P21+Q21+R21 -> 1920.5414 | U21: =T21/$R$2 -> 71.131165 | V21: =+U21/8 -> 8.8913956 | X21: =A21 -> 15 | Y21: =B21 -> Quispe Pacco Obita | Z21: =AA21-S21 -> 326.12814 | AA21: =1775+100+125 -> 2000 | AB21: =T21+Z21 -> 2246.6696 | AC21: =AB21/$R$2 -> 83.209985 | AD21: =+AC21/8 -> 10.401248 | AF21: =Z21/$R$1 -> 1.5098525
A22: 16 | B22: Aragon Hancco Delia Jesusa | C22: INT M | D22: =37.6666666666667*$R$3 -> 1167.6667 | F22: 113 | G22: 103.58 | H22: =SUM(D22:G22) -> 1384.2467 | I22: =H22*$E$71 -> 157.38885 | J22: =H22-I22 -> 1226.8578 | K22: =((D22+E22+F22)*(9.72%)) -> 124.4808 | L22: =(D22+E22+F22)*(16.66%) -> 213.35907 | M22: =L22*6% -> 12.801544 | N22: =(1130*30%)/(30)*29 -> 327.7 | O22: =H22*6% -> 83.0548 | P22: =((H22*(0.63%))*1.18) -> 10.29049 | Q22: =(H22*(0.57%))*1.18 -> 9.3104431 | R22: =(H22*(0.55%))*1.18 -> 8.9837609 | S22: =J22+K22+L22+M22+N22 -> 1905.1992 | T22: =H22+K22+L22+M22+N22+O22+P22+Q22+R22 -> 2174.2276 | U22: =T22/$R$2 -> 80.526947 | V22: =+U22/8 -> 10.065868 | X22: =A22 -> 16 | Y22: =B22 -> Aragon Hancco Delia Jesusa | Z22: =AA22-S22 -> 242.80077 | AA22: =1923+100+125 -> 2148 | AB22: =T22+Z22 -> 2417.0283 | AC22: =AB22/$R$2 -> 89.519568 | AD22: =+AC22/8 -> 11.189946 | AF22: =Z22/$R$1 -> 1.1240776
A23: 17 | B23: Gonzales Aparicio Lisbeth | C23: INT M | D23: =37.6666666666667*$R$3 -> 1167.6667 | G23: 94.16 | H23: =SUM(D23:G23) -> 1261.8267 | I23: =H23*$E$71 -> 143.46969 | J23: =H23-I23 -> 1118.357 | K23: =((D23+E23+F23)*(9.72%)) -> 113.4972 | L23: =(D23+E23+F23)*(16.66%) -> 194.53327 | M23: =L23*6% -> 11.671996 | N23: =(1130*30%)/(30)*30 -> 339 | O23: =H23*6% -> 75.7096 | P23: =((H23*(0.63%))*1.18) -> 9.3804194 | Q23: =(H23*(0.57%))*1.18 -> 8.4870462 | R23: =(H23*(0.55%))*1.18 -> 8.1892551 | S23: =J23+K23+L23+M23+N23 -> 1777.0594 | T23: =H23+K23+L23+M23+N23+O23+P23+Q23+R23 -> 2022.2955 | U23: =T23/$R$2 -> 74.899831 | V23: =+U23/8 -> 9.3624789 | X23: =A23 -> 17 | Y23: =B23 -> Gonzales Aparicio Lisbeth | Z23: =AA23-S23 -> 370.94056 | AA23: =1923+100+125 -> 2148 | AB23: =T23+Z23 -> 2393.236 | AC23: =AB23/$R$2 -> 88.638371 | AD23: =+AC23/8 -> 11.079796 | AF23: =Z23/$R$1 -> 1.7173174
A24: 18 | B24: Sánchez Huanca María Luisa | C24: PRO M | D24: =37.6666666666667*$R$3 -> 1167.6667 | F24: 113 | G24: 103.58 | H24: =SUM(D24:G24) -> 1384.2467 | I24: =H24*$E$70 -> 157.38885 | J24: =H24-I24 -> 1226.8578 | K24: =((D24+E24+F24)*(9.72%)) -> 124.4808 | L24: =(D24+E24+F24)*(16.66%) -> 213.35907 | M24: =L24*6% -> 12.801544 | N24: =(1130*30%)/(30)*30 -> 339 | O24: =H24*6% -> 83.0548 | P24: =((H24*(0.63%))*1.18) -> 10.29049 | Q24: =(H24*(0.57%))*1.18 -> 9.3104431 | R24: =(H24*(0.55%))*1.18 -> 8.9837609 | S24: =J24+K24+L24+M24+N24 -> 1916.4992 | T24: =H24+K24+L24+M24+N24+O24+P24+Q24+R24 -> 2185.5276 | U24: =T24/$R$2 -> 80.945466 | V24: =+U24/8 -> 10.118183 | X24: =A24 -> 18 | Y24: =B24 -> Sánchez Huanca María Luisa | Z24: =AA24-S24 -> 231.50077 | AA24: =1923+100+125 -> 2148 | AB24: =T24+Z24 -> 2417.0283 | AC24: =AB24/$R$2 -> 89.519568 | AD24: =+AC24/8 -> 11.189946 | AF24: =Z24/$R$1 -> 1.0717628
A25: 19 | B25: Alvarez Chavez, Richard | C25: PRO F | D25: =37.6666666666667*$R$3 -> 1167.6667 | F25: 113 | H25: =SUM(D25:G25) -> 1280.6667 | I25: =H25*$D$66 -> 167.25507 | J25: =H25-I25 -> 1113.4116 | K25: =((D25+E25+F25)*(9.72%)) -> 124.4808 | L25: =(D25+E25+F25)*(16.66%) -> 213.35907 | M25: =L25*6% -> 12.801544 | N25: =(1130*30%)/(30)*30 -> 339 | O25: =H25*6% -> 76.84 | P25: =((H25*(0.63%))*1.18) -> 9.520476 | Q25: =(H25*(0.57%))*1.18 -> 8.613764 | R25: =(H25*(0.55%))*1.18 -> 8.3115267 | S25: =J25+K25+L25+M25+N25 -> 1803.053 | T25: =H25+K25+L25+M25+N25+O25+P25+Q25+R25 -> 2073.5938 | U25: =T25/$R$2 -> 76.799772 | V25: =+U25/8 -> 9.5999715 | X25: =A25 -> 19 | Y25: =B25 -> Alvarez Chavez, Richard | Z25: =AA25-S25 -> 386.94699 | AA25: =1925+140+125 -> 2190 | AB25: =T25+Z25 -> 2460.5408 | AC25: =AB25/$R$2 -> 91.131142 | AD25: =+AC25/8 -> 11.391393 | AF25: =Z25/$R$1 -> 1.7914212
A26: 20 | B26: Aparicio Ch Claver | C26: PRO F | D26: =37.6666666666667*$R$3 -> 1167.6667 | F26: 113 | H26: =SUM(D26:G26) -> 1280.6667 | I26: =H26*$D$66 -> 167.25507 | J26: =H26-I26 -> 1113.4116 | K26: =((D26+E26+F26)*(9.72%)) -> 124.4808 | L26: =(D26+E26+F26)*(16.66%) -> 213.35907 | M26: =L26*6% -> 12.801544 | N26: =(1130*30%)/(30)*30 -> 339 | O26: =H26*6% -> 76.84 | P26: =((H26*(0.63%))*1.18) -> 9.520476 | Q26: =(H26*(0.57%))*1.18 -> 8.613764 | R26: =(H26*(0.55%))*1.18 -> 8.3115267 | S26: =J26+K26+L26+M26+N26 -> 1803.053 | T26: =H26+K26+L26+M26+N26+O26+P26+Q26+R26 -> 2073.5938 | U26: =T26/$R$2 -> 76.799772 | V26: =+U26/8 -> 9.5999715 | X26: =A26 -> 20 | Y26: =B26 -> Aparicio Ch Claver | Z26: =AA26-S26 -> 386.94699 | AA26: =1925+140+125 -> 2190 | AB26: =T26+Z26 -> 2460.5408 | AC26: =AB26/$R$2 -> 91.131142 | AD26: =+AC26/8 -> 11.391393 | AF26: =Z26/$R$1 -> 1.7914212
A27: 21 | B27: Aquino Gomez Carmelo | C27: PRO F | D27: =37.6666666666667*$R$3 -> 1167.6667 | F27: 113 | H27: =SUM(D27:G27) -> 1280.6667 | I27: =H27*$D$66 -> 167.25507 | J27: =H27-I27 -> 1113.4116 | K27: =((D27+E27+F27)*(9.72%)) -> 124.4808 | L27: =(D27+E27+F27)*(16.66%) -> 213.35907 | M27: =L27*6% -> 12.801544 | N27: =(1130*30%)/(30)*30 -> 339 | O27: =H27*6% -> 76.84 | P27: =((H27*(0.63%))*1.18) -> 9.520476 | Q27: =(H27*(0.57%))*1.18 -> 8.613764 | R27: =(H27*(0.55%))*1.18 -> 8.3115267 | S27: =J27+K27+L27+M27+N27 -> 1803.053 | T27: =H27+K27+L27+M27+N27+O27+P27+Q27+R27 -> 2073.5938 | U27: =T27/$R$2 -> 76.799772 | V27: =+U27/8 -> 9.5999715 | X27: =A27 -> 21 | Y27: =B27 -> Aquino Gomez Carmelo | Z27: =AA27-S27 -> 246.94699 | AA27: =1825+100+125 -> 2050 | AB27: =T27+Z27 -> 2320.5408 | AC27: =AB27/$R$2 -> 85.945957 | AD27: =+AC27/8 -> 10.743245 | AF27: =Z27/$R$1 -> 1.1432731
A28: 22 | B28: Ayamamani Chura Elver Emilio | C28: PRO F | D28: =37.6666666666667*$R$3 -> 1167.6667 | E28: 27.77 | F28: 113 | H28: =SUM(D28:G28) -> 1308.4367 | I28: =H28*$D$66 -> 170.88183 | J28: =H28-I28 -> 1137.5548 | K28: =((D28+E28+F28)*(9.72%)) -> 127.18004 | L28: =(D28+E28+F28)*(16.66%) -> 217.98555 | M28: =L28*6% -> 13.079133 | N28: =(1130*30%)/(30)*30 -> 339 | O28: =H28*6% -> 78.5062 | P28: =((H28*(0.63%))*1.18) -> 9.7269182 | Q28: =(H28*(0.57%))*1.18 -> 8.800545 | R28: =(H28*(0.55%))*1.18 -> 8.491754 | S28: =J28+K28+L28+M28+N28 -> 1834.7996 | T28: =H28+K28+L28+M28+N28+O28+P28+Q28+R28 -> 2111.2068 | U28: =T28/$R$2 -> 78.192845 | V28: =+U28/8 -> 9.7741056 | X28: =A28 -> 22 | Y28: =B28 -> Ayamamani Chura Elver Emilio | Z28: =AA28-S28 -> 690.20044 | AA28: =2300+100+125 -> 2525 | AB28: =T28+Z28 -> 2801.4072 | AC28: =AB28/$R$2 -> 103.75582 | AD28: =+AC28/8 -> 12.969478 | AF28: =Z28/$R$1 -> 3.1953724
A29: 23 | B29: Cañari Pucho, Guillermo | C29: INT F | D29: =37.6666666666667*$R$3 -> 1167.6667 | H29: =SUM(D29:G29) -> 1167.6667 | I29: =H29*$D$64 -> 150.86253 | J29: =H29-I29 -> 1016.8041 | K29: =((D29+E29+F29)*(9.72%)) -> 113.4972 | L29: =(D29+E29+F29)*(16.66%) -> 194.53327 | M29: =L29*6% -> 11.671996 | N29: =(1130*30%)/(30)*30 -> 339 | O29: =H29*6% -> 70.06 | P29: =((H29*(0.63%))*1.18) -> 8.680434 | Q29: =(H29*(0.57%))*1.18 -> 7.853726 | R29: =(H29*(0.55%))*1.18 -> 7.5781567 | S29: =J29+K29+L29+M29+N29 -> 1675.5066 | T29: =H29+K29+L29+M29+N29+O29+P29+Q29+R29 -> 1920.5414 | U29: =T29/$R$2 -> 71.131165 | V29: =+U29/8 -> 8.8913956 | X29: =A29 -> 23 | Y29: =B29 -> Cañari Pucho, Guillermo | Z29: =AA29-S29 -> 324.4934 | AA29: =1775+100+125 -> 2000 | AB29: =T29+Z29 -> 2245.0349 | AC29: =AB29/$R$2 -> 83.149439 | AD29: =+AC29/8 -> 10.39368 | AF29: =Z29/$R$1 -> 1.5022843
A30: 24 | B30: Ccanchi Neira, Juan Lorenzo | C30: PRO F | D30: =37.6666666666667*$R$3 -> 1167.6667 | H30: =SUM(D30:G30) -> 1167.6667 | I30: =H30*$D$66 -> 152.49727 | J30: =H30-I30 -> 1015.1694 | K30: =((D30+E30+F30)*(9.72%)) -> 113.4972 | L30: =(D30+E30+F30)*(16.66%) -> 194.53327 | M30: =L30*6% -> 11.671996 | N30: =(1130*30%)/(30)*30 -> 339 | O30: =H30*6% -> 70.06 | P30: =((H30*(0.63%))*1.18) -> 8.680434 | Q30: =(H30*(0.57%))*1.18 -> 7.853726 | R30: =(H30*(0.55%))*1.18 -> 7.5781567 | S30: =J30+K30+L30+M30+N30 -> 1673.8719 | T30: =H30+K30+L30+M30+N30+O30+P30+Q30+R30 -> 1920.5414 | U30: =T30/$R$2 -> 71.131165 | V30: =+U30/8 -> 8.8913956 | X30: =A30 -> 24 | Y30: =B30 -> Ccanchi Neira, Juan Lorenzo | Z30: =AA30-S30 -> 326.12814 | AA30: =1775+100+125 -> 2000 | AB30: =T30+Z30 -> 2246.6696 | AC30: =AB30/$R$2 -> 83.209985 | AD30: =+AC30/8 -> 10.401248 | AF30: =Z30/$R$1 -> 1.5098525
A31: 25 | B31: Gamarra Chambi, Ernesto | C31: SNP | D31: =37.6666666666667*$R$3 -> 1167.6667 | H31: =SUM(D31:G31) -> 1167.6667 | I31: =H31*$E$69 -> 151.79667 | J31: =H31-I31 -> 1015.87 | K31: =((D31+E31+F31)*(9.72%)) -> 113.4972 | L31: =(D31+E31+F31)*(16.66%) -> 194.53327 | M31: =L31*6% -> 11.671996 | N31: =(1130*30%)/(30)*30 -> 339 | O31: =H31*6% -> 70.06 | P31: =((H31*(0.63%))*1.18) -> 8.680434 | Q31: =(H31*(0.57%))*1.18 -> 7.853726 | R31: =(H31*(0.55%))*1.18 -> 7.5781567 | S31: =J31+K31+L31+M31+N31 -> 1674.5725 | T31: =H31+K31+L31+M31+N31+O31+P31+Q31+R31 -> 1920.5414 | U31: =T31/$R$2 -> 71.131165 | V31: =+U31/8 -> 8.8913956 | X31: =A31 -> 25 | Y31: =B31 -> Gamarra Chambi, Ernesto | Z31: =AA31-S31 -> 325.42754 | AA31: =1775+100+125 -> 2000 | AB31: =T31+Z31 -> 2245.969 | AC31: =AB31/$R$2 -> 83.184036 | AD31: =+AC31/8 -> 10.398005 | AF31: =Z31/$R$1 -> 1.506609
A32: 26 | B32: Huaynacho Otazu, Donar | C32: PRO M | D32: =37.6666666666667*$R$3 -> 1167.6667 | F32: 113 | H32: =SUM(D32:G32) -> 1280.6667 | I32: =H32*$E$70 -> 145.6118 | J32: =H32-I32 -> 1135.0549 | K32: =((D32+E32+F32)*(9.72%)) -> 124.4808 | L32: =(D32+E32+F32)*(16.66%) -> 213.35907 | M32: =L32*6% -> 12.801544 | N32: =(1130*30%)/(30)*30 -> 339 | O32: =H32*6% -> 76.84 | P32: =((H32*(0.63%))*1.18) -> 9.520476 | Q32: =(H32*(0.57%))*1.18 -> 8.613764 | R32: =(H32*(0.55%))*1.18 -> 8.3115267 | S32: =J32+K32+L32+M32+N32 -> 1824.6963 | T32: =H32+K32+L32+M32+N32+O32+P32+Q32+R32 -> 2073.5938 | U32: =T32/$R$2 -> 76.799772 | V32: =+U32/8 -> 9.5999715 | X32: =A32 -> 26 | Y32: =B32 -> Huaynacho Otazu, Donar | Z32: =AA32-S32 -> 225.30372 | AA32: =1825+100+125 -> 2050 | AB32: =T32+Z32 -> 2298.8976 | AC32: =AB32/$R$2 -> 85.144354 | AD32: =+AC32/8 -> 10.643044 | AF32: =Z32/$R$1 -> 1.0430728
A33: 27 | B33: Huaynapata Itusaca Yoni Angel | C33: PRI M | D33: =37.6666666666667*$R$3 -> 1167.6667 | F33: 113 | H33: =SUM(D33:G33) -> 1280.6667 | I33: =H33*$E$72 -> 145.6118 | J33: =H33-I33 -> 1135.0549 | K33: =((D33+E33+F33)*(9.72%)) -> 124.4808 | L33: =(D33+E33+F33)*(16.66%) -> 213.35907 | M33: =L33*6% -> 12.801544 | N33: =(1130*30%)/(30)*30 -> 339 | O33: =H33*6% -> 76.84 | P33: =((H33*(0.63%))*1.18) -> 9.520476 | Q33: =(H33*(0.57%))*1.18 -> 8.613764 | R33: =(H33*(0.55%))*1.18 -> 8.3115267 | S33: =J33+K33+L33+M33+N33 -> 1824.6963 | T33: =H33+K33+L33+M33+N33+O33+P33+Q33+R33 -> 2073.5938 | U33: =T33/$R$2 -> 76.799772 | V33: =+U33/8 -> 9.5999715 | X33: =A33 -> 27 | Y33: =B33 -> Huaynapata Itusaca Yoni Angel | Z33: =AA33-S33 -> 225.30372 | AA33: =1925+125 -> 2050 | AB33: =T33+Z33 -> 2298.8976 | AC33: =AB33/$R$2 -> 85.144354 | AD33: =+AC33/8 -> 10.643044 | AF33: =Z33/$R$1 -> 1.0430728
A34: 28 | B34: Idme Huaraccallo, Agustin | C34: PRO F | D34: =37.6666666666667*$R$3 -> 1167.6667 | H34: =SUM(D34:G34) -> 1167.6667 | I34: =H34*$D$66 -> 152.49727 | J34: =H34-I34 -> 1015.1694 | K34: =((D34+E34+F34)*(9.72%)) -> 113.4972 | L34: =(D34+E34+F34)*(16.66%) -> 194.53327 | M34: =L34*6% -> 11.671996 | N34: =(1130*30%)/(30)*30 -> 339 | O34: =H34*6% -> 70.06 | P34: =((H34*(0.63%))*1.18) -> 8.680434 | Q34: =(H34*(0.57%))*1.18 -> 7.853726 | R34: =(H34*(0.55%))*1.18 -> 7.5781567 | S34: =J34+K34+L34+M34+N34 -> 1673.8719 | T34: =H34+K34+L34+M34+N34+O34+P34+Q34+R34 -> 1920.5414 | U34: =T34/$R$2 -> 71.131165 | V34: =+U34/8 -> 8.8913956 | X34: =A34 -> 28 | Y34: =B34 -> Idme Huaraccallo, Agustin | Z34: =AA34-S34 -> 376.12814 | AA34: =1825+100+125 -> 2050 | AB34: =T34+Z34 -> 2296.6696 | AC34: =AB34/$R$2 -> 85.061836 | AD34: =+AC34/8 -> 10.63273 | AF34: =Z34/$R$1 -> 1.741334
A35: 29 | B35: Lope Choquehuanca, Cirilo | C35: PROF | D35: =37.6666666666667*$R$3 -> 1167.6667 | H35: =SUM(D35:G35) -> 1167.6667 | I35: 0 | J35: =H35-I35 -> 1167.6667 | K35: =((D35+E35+F35)*(9.72%)) -> 113.4972 | L35: =(D35+E35+F35)*(16.66%) -> 194.53327 | M35: =L35*6% -> 11.671996 | N35: =(1130*30%)/(30)*30 -> 339 | O35: =H35*6% -> 70.06 | P35: =((H35*(0.63%))*1.18) -> 8.680434 | Q35: =(H35*(0.57%))*1.18 -> 7.853726 | R35: =(H35*(0.55%))*1.18 -> 7.5781567 | S35: =J35+K35+L35+M35+N35 -> 1826.3691 | T35: =H35+K35+L35+M35+N35+O35+P35+Q35+R35 -> 1920.5414 | U35: =T35/$R$2 -> 71.131165 | V35: =+U35/8 -> 8.8913956 | X35: =A35 -> 29 | Y35: =B35 -> Lope Choquehuanca, Cirilo | Z35: =AA35-S35 -> 884.63087 | AA35: =2361+125+100+125 -> 2711 | AB35: =T35+Z35 -> 2805.1723 | AC35: =AB35/$R$2 -> 103.89527 | AD35: =+AC35/8 -> 12.986909 | AF35: =Z35/$R$1 -> 4.0955133
A36: 30 | B36: Lope Choquehuanca, Luis | C36: SNP | D36: =37.6666666666667*$R$3 -> 1167.6667 | H36: =SUM(D36:G36) -> 1167.6667 | I36: 0 | J36: =H36-I36 -> 1167.6667 | K36: =((D36+E36+F36)*(9.72%)) -> 113.4972 | L36: =(D36+E36+F36)*(16.66%) -> 194.53327 | M36: =L36*6% -> 11.671996 | N36: =(1130*30%)/(30)*30 -> 339 | O36: =H36*6% -> 70.06 | P36: =((H36*(0.63%))*1.18) -> 8.680434 | Q36: =(H36*(0.57%))*1.18 -> 7.853726 | R36: =(H36*(0.55%))*1.18 -> 7.5781567 | S36: =J36+K36+L36+M36+N36 -> 1826.3691 | T36: =H36+K36+L36+M36+N36+O36+P36+Q36+R36 -> 1920.5414 | U36: =T36/$R$2 -> 71.131165 | V36: =+U36/8 -> 8.8913956 | X36: =A36 -> 30 | Y36: =B36 -> Lope Choquehuanca, Luis | Z36: =AA36-S36 -> 573.63087 | AA36: =1900+125+100+125+150 -> 2400 | AB36: =T36+Z36 -> 2494.1723 | AC36: =AB36/$R$2 -> 92.376752 | AD36: =+AC36/8 -> 11.547094 | AF36: =Z36/$R$1 -> 2.6556985
A37: 31 | B37: Lopez Mamani, Nestor | C37: SNP | D37: =37.6666666666667*$R$3 -> 1167.6667 | F37: 113 | H37: =SUM(D37:G37) -> 1280.6667 | I37: =H37*$E$69 -> 166.48667 | J37: =H37-I37 -> 1114.18 | K37: =((D37+E37+F37)*(9.72%)) -> 124.4808 | L37: =(D37+E37+F37)*(16.66%) -> 213.35907 | M37: =L37*6% -> 12.801544 | N37: =(1130*30%)/(30)*30 -> 339 | O37: =H37*6% -> 76.84 | P37: =((H37*(0.63%))*1.18) -> 9.520476 | Q37: =(H37*(0.57%))*1.18 -> 8.613764 | R37: =(H37*(0.55%))*1.18 -> 8.3115267 | S37: =J37+K37+L37+M37+N37 -> 1803.8214 | T37: =H37+K37+L37+M37+N37+O37+P37+Q37+R37 -> 2073.5938 | U37: =T37/$R$2 -> 76.799772 | V37: =+U37/8 -> 9.5999715 | X37: =A37 -> 31 | Y37: =B37 -> Lopez Mamani, Nestor | Z37: =AA37-S37 -> 386.17859 | AA37: =1925+140+125 -> 2190 | AB37: =T37+Z37 -> 2459.7724 | AC37: =AB37/$R$2 -> 91.102683 | AD37: =+AC37/8 -> 11.387835 | AF37: =Z37/$R$1 -> 1.7878638
A38: 32 | B38: Mamani Anconaira, Santo Domingo | C38: SNP | D38: =37.6666666666667*$R$3 -> 1167.6667 | F38: 113 | H38: =SUM(D38:G38) -> 1280.6667 | I38: =H38*$E$69 -> 166.48667 | J38: =H38-I38 -> 1114.18 | K38: =((D38+E38+F38)*(9.72%)) -> 124.4808 | L38: =(D38+E38+F38)*(16.66%) -> 213.35907 | M38: =L38*6% -> 12.801544 | N38: =(1130*30%)/(30)*30 -> 339 | O38: =H38*6% -> 76.84 | P38: =((H38*(0.63%))*1.18) -> 9.520476 | Q38: =(H38*(0.57%))*1.18 -> 8.613764 | R38: =(H38*(0.55%))*1.18 -> 8.3115267 | S38: =J38+K38+L38+M38+N38 -> 1803.8214 | T38: =H38+K38+L38+M38+N38+O38+P38+Q38+R38 -> 2073.5938 | U38: =T38/$R$2 -> 76.799772 | V38: =+U38/8 -> 9.5999715 | X38: =A38 -> 32 | Y38: =B38 -> Mamani Anconaira, Santo Domingo | Z38: =AA38-S38 -> 196.17859 | AA38: =1775+100+125 -> 2000 | AB38: =T38+Z38 -> 2269.7724 | AC38: =AB38/$R$2 -> 84.065646 | AD38: =+AC38/8 -> 10.508206 | AF38: =Z38/$R$1 -> 0.90823421
A39: 33 | B39: Mamani Idme, Vicente | C39: PRO F | D39: =37.6666666666667*$R$3 -> 1167.6667 | E39: 106.8999 | F39: 113 | H39: =SUM(D39:G39) -> 1387.5666 | I39: =H39*$D$66 -> 181.21619 | J39: =H39-I39 -> 1206.3504 | K39: =((D39+E39+F39)*(9.72%)) -> 134.87147 | L39: =(D39+E39+F39)*(16.66%) -> 231.16859 | M39: =L39*6% -> 13.870115 | N39: =(1130*30%)/(30)*30 -> 339 | O39: =H39*6% -> 83.253994 | P39: =((H39*(0.63%))*1.18) -> 10.31517 | Q39: =(H39*(0.57%))*1.18 -> 9.3327727 | R39: =(H39*(0.55%))*1.18 -> 9.005307 | S39: =J39+K39+L39+M39+N39 -> 1925.2605 | T39: =H39+K39+L39+M39+N39+O39+P39+Q39+R39 -> 2218.384 | U39: =T39/$R$2 -> 82.16237 | V39: =+U39/8 -> 10.270296 | X39: =A39 -> 33 | Y39: =B39 -> Mamani Idme, Vicente | Z39: =AA39-S39 -> 1924.7395 | AA39: =3625+100+125 -> 3850 | AB39: =T39+Z39 -> 4143.1234 | AC39: =AB39/$R$2 -> 153.44902 | AD39: =+AC39/8 -> 19.181127 | AF39: =Z39/$R$1 -> 8.9108308
A40: 34 | B40: Mamani Mamani, Alejandro | C40: PRO M | D40: =37.6666666666667*$R$3 -> 1167.6667 | H40: =SUM(D40:G40) -> 1167.6667 | I40: =H40*$E$70 -> 132.7637 | J40: =H40-I40 -> 1034.903 | K40: =((D40+E40+F40)*(9.72%)) -> 113.4972 | L40: =(D40+E40+F40)*(16.66%) -> 194.53327 | M40: =L40*6% -> 11.671996 | N40: =(1130*30%)/(30)*30 -> 339 | O40: =H40*6% -> 70.06 | P40: =((H40*(0.63%))*1.18) -> 8.680434 | Q40: =(H40*(0.57%))*1.18 -> 7.853726 | R40: =(H40*(0.55%))*1.18 -> 7.5781567 | S40: =J40+K40+L40+M40+N40 -> 1693.6054 | T40: =H40+K40+L40+M40+N40+O40+P40+Q40+R40 -> 1920.5414 | U40: =T40/$R$2 -> 71.131165 | V40: =+U40/8 -> 8.8913956 | X40: =A40 -> 34 | Y40: =B40 -> Mamani Mamani, Alejandro | Z40: =AA40-S40 -> 596.39457 | AA40: =2025+140+125 -> 2290 | AB40: =T40+Z40 -> 2516.936 | AC40: =AB40/$R$2 -> 93.219852 | AD40: =+AC40/8 -> 11.652482 | AF40: =Z40/$R$1 -> 2.761086
...

Sheet PLAME
AP1: =AP2*8 -> 216 | AQ1: Horas
AP2: 27 | AQ2: Dias laborables
AP3: 31 | AQ3: Dias
A4: MES DE ENERO 2026
A5: Nº | B5: NOMBRES | C5: SPP o SNP | D5: INFORMACION | F5: SUSPENSION PERFECTA | N5: SUSPENSIÓN IMPERFECTA | Y5: INGRESOS | AH5: DESCUENTOS | AM5: NETO A PAGAR | AN5: APORTES DEL EMPLEADOR
D6: PENSIONISTA | E6: EDAD | F6: 01 - S.P. Sanción disciplinaria | G6: 02 - S.P. Ejercicio del derecho de huelga | H6: 03 - Detención del trabajador, salvo el caso de c | I6: 04 - Inhabilitación administrativa o judicial por | J6: 05 - Permiso o licencia concedidos por el emplea | K6: 06 - Caso fortuito o fuerza mayor | L6: 08 - Falta no justificada | M6: 08 - Por temporada o intermitente | N6: 20 - Enfermedad o accidente (primeros veinte días) | O6: 21 - Incapacidad temporal (invalidez, enfermeda | P6: 22 - Maternidad durante el descanso pre y post na | Q6: 23 - Descanso vacacional | R6: 24 - Licencia para desempeñar cargo cívico y p | S6: 25 - Permiso y licencia para el desempeño de carg | T6: 26 - Licencia con goce de haber | U6: 27 - Días compensados por horas trabajadas en so | V6: DIAS NO LABORADOS | W6: DIAS LABORADOS | X6: TOTAL HORAS | Y6: 0117 - COMP. VACACIONAL | Z6: 0118 - REM. VAC. | AA6: 0121 - REM. JORN. BAS. | AB6: 0201 - ASIG. FAMILIAR | AC6: REMUNERACION BRUTA | AD6: 0312 - BONIF. EXT. TEMP. | AE6: 0314 - BETA 30 % | AF6: 0406 - GRATIF. FIEST. P. NAV. | AG6: 0904 - CTS | AH6: 0601 - COMI. AFP % | AI6: 0605 - RENTA 5TA CAT. RET. | AJ6: 0606 - PRIMA DE SEG. AFP | AK6: 0607 - SNP | AL6: 0608 - SPP APORT. OBL. | AN6: 0803 - POLIZA | AO6: 0804 - ESSALUD | AP6: 0805 - SCTR | AQ6: 0810 - EPS
A7: 1 | B7: Apaza Tito Patricia | C7: PRO F | V7: =SUM(L7:Q7) -> 0 | W7: =$AP$3-V7 -> 31 | X7: ='REPORTE DIARIO'!AI7 -> 216 | Y7: =PROYECTADA!G7 -> 0 | Z7: =1130/30*Q7 -> 0 | AA7: =PROYECTADA!D7/$AP$1*PLAME!X7 -> 1167.6667 | AB7: =PROYECTADA!F7/$AP$3*($AP$3-L7) -> 0 | AC7: =SUM(Z7:AB7) -> 1167.6667 | AD7: =6%*AF7 -> 11.671996 | AE7: =((30%*1130)/$AP$3)*($AP$3-L7) -> 339 | AF7: =16.66%*AC7 -> 194.53327 | AG7: =9.72%*AC7 -> 113.4972 | AH7: =IF(OR(D7="SI", C7="SNP"), 0, VLOOKUP(C7, tbl_descuentos[], 2, FALSE) * SUM(Y7:AB7)) -> 19.733567 | AI7: 0 | AJ7: =IF(OR(D7="SI", C7="SNP"), 0, VLOOKUP(C7, tbl_descuentos[], IF(E7 > 65, 4, 3), FALSE) * SUM(Y7:AB7)) -> 15.997033 | AK7: =IF(D7="SI",0,IF(C7="SNP",13%*SUM(Y7:AB7),0)) -> 0 | AL7: =IF(C7="SNP",0,IF(D7="SI",0,10%*(AC7+Y7))) -> 116.76667 | AM7: =SUMPRODUCT(ROUND(Y7:AB7, 2)) + SUMPRODUCT(ROUND(AD7:AG7, 2)) - SUMPRODUCT(ROUND(AH7:AL7, 2)) -> 1673.87 | AN7: =PROYECTADA!P7 -> 9.609684 | AO7: =6%*SUM(Y7:AB7) -> 70.06 | AP7: =PROYECTADA!Q7 -> 8.694476 | AQ7: =PROYECTADA!R7 -> 8.3894067 | AX7: =IF(AND(AM7=AS7,AN7,AT7,AO7,AU7,AP7,AV7,AQ7,AW7),"OK","ERROR") -> ERROR
A8: 2 | B8: Aquino Gómez Basilia Isabel | C8: PRO F | V8: =SUM(L8:Q8) -> 0 | W8: =$AP$3-V8 -> 31 | X8: ='REPORTE DIARIO'!AI8 -> 216 | Y8: =PROYECTADA!G8 -> 0 | Z8: =1130/30*Q8 -> 0 | AA8: =PROYECTADA!D8/$AP$1*PLAME!X8 -> 1167.6667 | AB8: =PROYECTADA!F8/$AP$3*($AP$3-L8) -> 0 | AC8: =SUM(Z8:AB8) -> 1167.6667 | AD8: =6%*AF8 -> 11.671996 | AE8: =((30%*1130)/$AP$3)*($AP$3-L8) -> 339 | AF8: =16.66%*AC8 -> 194.53327 | AG8: =9.72%*AC8 -> 113.4972 | AH8: =IF(OR(D8="SI", C8="SNP"), 0, VLOOKUP(C8, tbl_descuentos[], 2, FALSE) * SUM(Y8:AB8)) -> 19.733567 | AI8: 0 | AJ8: =IF(OR(D8="SI", C8="SNP"), 0, VLOOKUP(C8, tbl_descuentos[], IF(E8 > 65, 4, 3), FALSE) * SUM(Y8:AB8)) -> 15.997033 | AK8: =IF(D8="SI",0,IF(C8="SNP",13%*SUM(Y8:AB8),0)) -> 0 | AL8: =IF(C8="SNP",0,IF(D8="SI",0,10%*(AC8+Y8))) -> 116.76667 | AM8: =SUMPRODUCT(ROUND(Y8:AB8, 2)) + SUMPRODUCT(ROUND(AD8:AG8, 2)) - SUMPRODUCT(ROUND(AH8:AL8, 2)) -> 1673.87 | AN8: =PROYECTADA!P8 -> 8.680434 | AO8: =6%*SUM(Y8:AB8) -> 70.06 | AP8: =PROYECTADA!Q8 -> 7.853726 | AQ8: =PROYECTADA!R8 -> 7.5781567 | AX8: =IF(AND(AM8=AS8,AN8,AT8,AO8,AU8,AP8,AV8,AQ8,AW8),"OK","ERROR") -> ERROR
A9: 3 | B9: Calla G Guillermina | C9: PRO F | V9: =SUM(L9:Q9) -> 0 | W9: =$AP$3-V9 -> 31 | X9: ='REPORTE DIARIO'!AI9 -> 216 | Y9: =PROYECTADA!G9 -> 0 | Z9: =1130/30*Q9 -> 0 | AA9: =PROYECTADA!D9/$AP$1*PLAME!X9 -> 1167.6667 | AB9: =PROYECTADA!F9/$AP$3*($AP$3-L9) -> 0 | AC9: =SUM(Z9:AB9) -> 1167.6667 | AD9: =6%*AF9 -> 11.671996 | AE9: =((30%*1130)/$AP$3)*($AP$3-L9) -> 339 | AF9: =16.66%*AC9 -> 194.53327 | AG9: =9.72%*AC9 -> 113.4972 | AH9: =IF(OR(D9="SI", C9="SNP"), 0, VLOOKUP(C9, tbl_descuentos[], 2, FALSE) * SUM(Y9:AB9)) -> 19.733567 | AI9: 0 | AJ9: =IF(OR(D9="SI", C9="SNP"), 0, VLOOKUP(C9, tbl_descuentos[], IF(E9 > 65, 4, 3), FALSE) * SUM(Y9:AB9)) -> 15.997033 | AK9: =IF(D9="SI",0,IF(C9="SNP",13%*SUM(Y9:AB9),0)) -> 0 | AL9: =IF(C9="SNP",0,IF(D9="SI",0,10%*(AC9+Y9))) -> 116.76667 | AM9: =SUMPRODUCT(ROUND(Y9:AB9, 2)) + SUMPRODUCT(ROUND(AD9:AG9, 2)) - SUMPRODUCT(ROUND(AH9:AL9, 2)) -> 1673.87 | AN9: =PROYECTADA!P9 -> 8.680434 | AO9: =6%*SUM(Y9:AB9) -> 70.06 | AP9: =PROYECTADA!Q9 -> 7.853726 | AQ9: =PROYECTADA!R9 -> 7.5781567 | AX9: =IF(AND(AM9=AS9,AN9,AT9,AO9,AU9,AP9,AV9,AQ9,AW9),"OK","ERROR") -> ERROR
A10: 4 | B10: Challco Laime, Gilberta | C10: HAB M | L10: 1 | V10: =SUM(L10:Q10) -> 1 | W10: =$AP$3-V10 -> 30 | X10: ='REPORTE DIARIO'!AI10 -> 208 | Y10: =PROYECTADA!G10 -> 0 | Z10: =1130/30*Q10 -> 0 | AA10: =PROYECTADA!D10/$AP$1*PLAME!X10 -> 1124.4198 | AB10: =PROYECTADA!F10/$AP$3*($AP$3-L10) -> 0 | AC10: =SUM(Z10:AB10) -> 1124.4198 | AD10: =6%*AF10 -> 11.2397 | AE10: =((30%*1130)/$AP$3)*($AP$3-L10) -> 328.06452 | AF10: =16.66%*AC10 -> 187.32833 | AG10: =9.72%*AC10 -> 109.2936 | AH10: =IF(OR(D10="SI", C10="SNP"), 0, VLOOKUP(C10, tbl_descuentos[], 2, FALSE) * SUM(Y10:AB10)) -> 0 | AI10: 0 | AJ10: =IF(OR(D10="SI", C10="SNP"), 0, VLOOKUP(C10, tbl_descuentos[], IF(E10 > 65, 4, 3), FALSE) * SUM(Y10:AB10)) -> 15.404551 | AK10: =IF(D10="SI",0,IF(C10="SNP",13%*SUM(Y10:AB10),0)) -> 0 | AL10: =IF(C10="SNP",0,IF(D10="SI",0,10%*(AC10+Y10))) -> 112.44198 | AM10: =SUMPRODUCT(ROUND(Y10:AB10, 2)) + SUMPRODUCT(ROUND(AD10:AG10, 2)) - SUMPRODUCT(ROUND(AH10:AL10, 2)) -> 1632.5 | AN10: =PROYECTADA!P10 -> 8.680434 | AO10: =6%*SUM(Y10:AB10) -> 67.465185 | AP10: =PROYECTADA!Q10 -> 7.853726 | AQ10: =PROYECTADA!R10 -> 7.5781567 | AS10: 1632.5 | AT10: 8.680434 | AU10: 67.465185 | AV10: 7.853726 | AW10: 7.5781567 | AX10: =IF(AND(AM10=AS10,AN10,AT10,AO10,AU10,AP10,AV10,AQ10,AW10),"OK","ERROR") -> OK
A11: 5 | B11: Choquehuayta Huallpa, Estefania | C11: PRO M | V11: =SUM(L11:Q11) -> 0 | W11: =$AP$3-V11 -> 31 | X11: ='REPORTE DIARIO'!AI11 -> 210 | Y11: =PROYECTADA!G11 -> 0 | Z11: =1130/30*Q11 -> 0 | AA11: =PROYECTADA!D11/$AP$1*PLAME!X11 -> 1135.2315 | AB11: =PROYECTADA!F11/$AP$3*($AP$3-L11) -> 113 | AC11: =SUM(Z11:AB11) -> 1248.2315 | AD11: =6%*AF11 -> 12.477322 | AE11: =((30%*1130)/$AP$3)*($AP$3-L11) -> 339 | AF11: =16.66%*AC11 -> 207.95536 | AG11: =9.72%*AC11 -> 121.3281 | AH11: =IF(OR(D11="SI", C11="SNP"), 0, VLOOKUP(C11, tbl_descuentos[], 2, FALSE) * SUM(Y11:AB11)) -> 0 | AI11: 0 | AJ11: =IF(OR(D11="SI", C11="SNP"), 0, VLOOKUP(C11, tbl_descuentos[], IF(E11 > 65, 4, 3), FALSE) * SUM(Y11:AB11)) -> 17.100771 | AK11: =IF(D11="SI",0,IF(C11="SNP",13%*SUM(Y11:AB11),0)) -> 0 | AL11: =IF(C11="SNP",0,IF(D11="SI",0,10%*(AC11+Y11))) -> 124.82315 | AM11: =SUMPRODUCT(ROUND(Y11:AB11, 2)) + SUMPRODUCT(ROUND(AD11:AG11, 2)) - SUMPRODUCT(ROUND(AH11:AL11, 2)) -> 1787.08 | AN11: =PROYECTADA!P11 -> 9.520476 | AO11: =6%*SUM(Y11:AB11) -> 74.893889 | AP11: =PROYECTADA!Q11 -> 8.613764 | AQ11: =PROYECTADA!R11 -> 8.3115267 | AX11: =IF(AND(AM11=AS11,AN11,AT11,AO11,AU11,AP11,AV11,AQ11,AW11),"OK","ERROR") -> ERROR
A12: 6 | B12: Idme Huaraccallo, Gladis | C12: SNP | V12: =SUM(L12:Q12) -> 0 | W12: =$AP$3-V12 -> 31 | X12: ='REPORTE DIARIO'!AI12 -> 216 | Y12: =PROYECTADA!G12 -> 0 | Z12: =1130/30*Q12 -> 0 | AA12: =PROYECTADA!D12/$AP$1*PLAME!X12 -> 1167.6667 | AB12: =PROYECTADA!F12/$AP$3*($AP$3-L12) -> 0 | AC12: =SUM(Z12:AB12) -> 1167.6667 | AD12: =6%*AF12 -> 11.671996 | AE12: =((30%*1130)/$AP$3)*($AP$3-L12) -> 339 | AF12: =16.66%*AC12 -> 194.53327 | AG12: =9.72%*AC12 -> 113.4972 | AH12: =IF(OR(D12="SI", C12="SNP"), 0, VLOOKUP(C12, tbl_descuentos[], 2, FALSE) * SUM(Y12:AB12)) -> 0 | AI12: 0 | AJ12: =IF(OR(D12="SI", C12="SNP"), 0, VLOOKUP(C12, tbl_descuentos[], IF(E12 > 65, 4, 3), FALSE) * SUM(Y12:AB12)) -> 0 | AK12: =IF(D12="SI",0,IF(C12="SNP",13%*SUM(Y12:AB12),0)) -> 151.79667 | AL12: =IF(C12="SNP",0,IF(D12="SI",0,10%*(AC12+Y12))) -> 0 | AM12: =SUMPRODUCT(ROUND(Y12:AB12, 2)) + SUMPRODUCT(ROUND(AD12:AG12, 2)) - SUMPRODUCT(ROUND(AH12:AL12, 2)) -> 1674.57 | AN12: =PROYECTADA!P12 -> 8.680434 | AO12: =6%*SUM(Y12:AB12) -> 70.06 | AP12: =PROYECTADA!Q12 -> 7.853726 | AQ12: =PROYECTADA!R12 -> 7.5781567 | AS12: 1674.57 | AT12: 8.680434 | AU12: 70.06 | AV12: 7.853726 | AW12: 7.5781567 | AX12: =IF(AND(AM12=AS12,AN12,AT12,AO12,AU12,AP12,AV12,AQ12,AW12),"OK","ERROR") -> OK
A13: 7 | B13: Jacha Gomez, Flavia | C13: INT F | V13: =SUM(L13:Q13) -> 0 | W13: =$AP$3-V13 -> 31 | X13: ='REPORTE DIARIO'!AI13 -> 184 | Y13: =PROYECTADA!G13 -> 0 | Z13: =1130/30*Q13 -> 0 | AA13: =PROYECTADA!D13/$AP$1*PLAME!X13 -> 994.67901 | AB13: =PROYECTADA!F13/$AP$3*($AP$3-L13) -> 0 | AC13: =SUM(Z13:AB13) -> 994.67901 | AD13: =6%*AF13 -> 9.9428114 | AE13: =((30%*1130)/$AP$3)*($AP$3-L13) -> 339 | AF13: =16.66%*AC13 -> 165.71352 | AG13: =9.72%*AC13 -> 96.6828 | AH13: =IF(OR(D13="SI", C13="SNP"), 0, VLOOKUP(C13, tbl_descuentos[], 2, FALSE) * SUM(Y13:AB13)) -> 15.417525 | AI13: 0 | AJ13: =IF(OR(D13="SI", C13="SNP"), 0, VLOOKUP(C13, tbl_descuentos[], IF(E13 > 65, 4, 3), FALSE) * SUM(Y13:AB13)) -> 13.627102 | AK13: =IF(D13="SI",0,IF(C13="SNP",13%*SUM(Y13:AB13),0)) -> 0 | AL13: =IF(C13="SNP",0,IF(D13="SI",0,10%*(AC13+Y13))) -> 99.467901 | AM13: =SUMPRODUCT(ROUND(Y13:AB13, 2)) + SUMPRODUCT(ROUND(AD13:AG13, 2)) - SUMPRODUCT(ROUND(AH13:AL13, 2)) -> 1477.49 | AN13: =PROYECTADA!P13 -> 8.680434 | AO13: =6%*SUM(Y13:AB13) -> 59.680741 | AP13: =PROYECTADA!Q13 -> 7.853726 | AQ13: =PROYECTADA!R13 -> 7.5781567 | AX13: =IF(AND(AM13=AS13,AN13,AT13,AO13,AU13,AP13,AV13,AQ13,AW13),"OK","ERROR") -> ERROR
A14: 8 | B14: Lerma Yanarico Elena | C14: PRO F | V14: =SUM(L14:Q14) -> 0 | W14: =$AP$3-V14 -> 31 | X14: ='REPORTE DIARIO'!AI14 -> 216 | Y14: =PROYECTADA!G14 -> 0 | Z14: =1130/30*Q14 -> 0 | AA14: =PROYECTADA!D14/$AP$1*PLAME!X14 -> 1167.6667 | AB14: =PROYECTADA!F14/$AP$3*($AP$3-L14) -> 113 | AC14: =SUM(Z14:AB14) -> 1280.6667 | AD14: =6%*AF14 -> 12.801544 | AE14: =((30%*1130)/$AP$3)*($AP$3-L14) -> 339 | AF14: =16.66%*AC14 -> 213.35907 | AG14: =9.72%*AC14 -> 124.4808 | AH14: =IF(OR(D14="SI", C14="SNP"), 0, VLOOKUP(C14, tbl_descuentos[], 2, FALSE) * SUM(Y14:AB14)) -> 21.643267 | AI14: 0 | AJ14: =IF(OR(D14="SI", C14="SNP"), 0, VLOOKUP(C14, tbl_descuentos[], IF(E14 > 65, 4, 3), FALSE) * SUM(Y14:AB14)) -> 17.545133 | AK14: =IF(D14="SI",0,IF(C14="SNP",13%*SUM(Y14:AB14),0)) -> 0 | AL14: =IF(C14="SNP",0,IF(D14="SI",0,10%*(AC14+Y14))) -> 128.06667 | AM14: =SUMPRODUCT(ROUND(Y14:AB14, 2)) + SUMPRODUCT(ROUND(AD14:AG14, 2)) - SUMPRODUCT(ROUND(AH14:AL14, 2)) -> 1803.05 | AN14: =PROYECTADA!P14 -> 9.520476 | AO14: =6%*SUM(Y14:AB14) -> 76.84 | AP14: =PROYECTADA!Q14 -> 8.613764 | AQ14: =PROYECTADA!R14 -> 8.3115267 | AX14: =IF(AND(AM14=AS14,AN14,AT14,AO14,AU14,AP14,AV14,AQ14,AW14),"OK","ERROR") -> ERROR
A15: 9 | B15: Machaca Calcina, Benedicta | C15: INT M | V15: =SUM(L15:Q15) -> 0 | W15: =$AP$3-V15 -> 31 | X15: ='REPORTE DIARIO'!AI15 -> 182 | Y15: =PROYECTADA!G15 -> 0 | Z15: =1130/30*Q15 -> 0 | AA15: =PROYECTADA!D15/$AP$1*PLAME!X15 -> 983.86728 | AB15: =PROYECTADA!F15/$AP$3*($AP$3-L15) -> 113 | AC15: =SUM(Z15:AB15) -> 1096.8673 | AD15: =6%*AF15 -> 10.964285 | AE15: =((30%*1130)/$AP$3)*($AP$3-L15) -> 339 | AF15: =16.66%*AC15 -> 182.73809 | AG15: =9.72%*AC15 -> 106.6155 | AH15: =IF(OR(D15="SI", C15="SNP"), 0, VLOOKUP(C15, tbl_descuentos[], 2, FALSE) * SUM(Y15:AB15)) -> 0 | AI15: 0 | AJ15: =IF(OR(D15="SI", C15="SNP"), 0, VLOOKUP(C15, tbl_descuentos[], IF(E15 > 65, 4, 3), FALSE) * SUM(Y15:AB15)) -> 15.027082 | AK15: =IF(D15="SI",0,IF(C15="SNP",13%*SUM(Y15:AB15),0)) -> 0 | AL15: =IF(C15="SNP",0,IF(D15="SI",0,10%*(AC15+Y15))) -> 109.68673 | AM15: =SUMPRODUCT(ROUND(Y15:AB15, 2)) + SUMPRODUCT(ROUND(AD15:AG15, 2)) - SUMPRODUCT(ROUND(AH15:AL15, 2)) -> 1611.47 | AN15: =PROYECTADA!P15 -> 9.520476 | AO15: =6%*SUM(Y15:AB15) -> 65.812037 | AP15: =PROYECTADA!Q15 -> 8.613764 | AQ15: =PROYECTADA!R15 -> 8.3115267 | AX15: =IF(AND(AM15=AS15,AN15,AT15,AO15,AU15,AP15,AV15,AQ15,AW15),"OK","ERROR") -> ERROR
A16: 10 | B16: Mamani Hancco, Elsa Teresa | C16: INT F | V16: =SUM(L16:Q16) -> 0 | W16: =$AP$3-V16 -> 31 | X16: ='REPORTE DIARIO'!AI16 -> 216 | Y16: =PROYECTADA!G16 -> 0 | Z16: =1130/30*Q16 -> 0 | AA16: =PROYECTADA!D16/$AP$1*PLAME!X16 -> 1167.6667 | AB16: =PROYECTADA!F16/$AP$3*($AP$3-L16) -> 113 | AC16: =SUM(Z16:AB16) -> 1280.6667 | AD16: =6%*AF16 -> 12.801544 | AE16: =((30%*1130)/$AP$3)*($AP$3-L16) -> 339 | AF16: =16.66%*AC16 -> 213.35907 | AG16: =9.72%*AC16 -> 124.4808 | AH16: =IF(OR(D16="SI", C16="SNP"), 0, VLOOKUP(C16, tbl_descuentos[], 2, FALSE) * SUM(Y16:AB16)) -> 19.850333 | AI16: 0 | AJ16: =IF(OR(D16="SI", C16="SNP"), 0, VLOOKUP(C16, tbl_descuentos[], IF(E16 > 65, 4, 3), FALSE) * SUM(Y16:AB16)) -> 17.545133 | AK16: =IF(D16="SI",0,IF(C16="SNP",13%*SUM(Y16:AB16),0)) -> 0 | AL16: =IF(C16="SNP",0,IF(D16="SI",0,10%*(AC16+Y16))) -> 128.06667 | AM16: =SUMPRODUCT(ROUND(Y16:AB16, 2)) + SUMPRODUCT(ROUND(AD16:AG16, 2)) - SUMPRODUCT(ROUND(AH16:AL16, 2)) -> 1804.84 | AN16: =PROYECTADA!P16 -> 9.520476 | AO16: =6%*SUM(Y16:AB16) -> 76.84 | AP16: =PROYECTADA!Q16 -> 8.613764 | AQ16: =PROYECTADA!R16 -> 8.3115267 | AX16: =IF(AND(AM16=AS16,AN16,AT16,AO16,AU16,AP16,AV16,AQ16,AW16),"OK","ERROR") -> ERROR
A17: 11 | B17: Mamani Itusaca de Perca Guzmila | C17: HAB M | V17: =SUM(L17:Q17) -> 0 | W17: =$AP$3-V17 -> 31 | X17: ='REPORTE DIARIO'!AI17 -> 208 | Y17: =PROYECTADA!G17 -> 0 | Z17: =1130/30*Q17 -> 0 | AA17: =PROYECTADA!D17/$AP$1*PLAME!X17 -> 1124.4198 | AB17: =PROYECTADA!F17/$AP$3*($AP$3-L17) -> 0 | AC17: =SUM(Z17:AB17) -> 1124.4198 | AD17: =6%*AF17 -> 11.2397 | AE17: =((30%*1130)/$AP$3)*($AP$3-L17) -> 339 | AF17: =16.66%*AC17 -> 187.32833 | AG17: =9.72%*AC17 -> 109.2936 | AH17: =IF(OR(D17="SI", C17="SNP"), 0, VLOOKUP(C17, tbl_descuentos[], 2, FALSE) * SUM(Y17:AB17)) -> 0 | AI17: 0 | AJ17: =IF(OR(D17="SI", C17="SNP"), 0, VLOOKUP(C17, tbl_descuentos[], IF(E17 > 65, 4, 3), FALSE) * SUM(Y17:AB17)) -> 15.404551 | AK17: =IF(D17="SI",0,IF(C17="SNP",13%*SUM(Y17:AB17),0)) -> 0 | AL17: =IF(C17="SNP",0,IF(D17="SI",0,10%*(AC17+Y17))) -> 112.44198 | AM17: =SUMPRODUCT(ROUND(Y17:AB17, 2)) + SUMPRODUCT(ROUND(AD17:AG17, 2)) - SUMPRODUCT(ROUND(AH17:AL17, 2)) -> 1643.44 | AN17: =PROYECTADA!P17 -> 8.680434 | AO17: =6%*SUM(Y17:AB17) -> 67.465185 | AP17: =PROYECTADA!Q17 -> 7.853726 | AQ17: =PROYECTADA!R17 -> 7.5781567 | AX17: =IF(AND(AM17=AS17,AN17,AT17,AO17,AU17,AP17,AV17,AQ17,AW17),"OK","ERROR") -> ERROR
A18: 12 | B18: Mayta Coaquira Janet Venancia | C18: INT M | Q18: 13 | V18: =SUM(L18:Q18) -> 13 | W18: =$AP$3-V18 -> 18 | X18: ='REPORTE DIARIO'!AI18 -> 120 | Y18: =PROYECTADA!G18 -> 0 | Z18: 489.63 | AA18: =PROYECTADA!D18/$AP$1*PLAME!X18 -> 648.7037 | AB18: =PROYECTADA!F18/$AP$3*($AP$3-L18) -> 0 | AC18: =SUM(Z18:AB18) -> 1138.3337 | AD18: =6%*AF18 -> 11.378784 | AE18: =((30%*1130)/$AP$3)*($AP$3-L18) -> 339 | AF18: =16.66%*AC18 -> 189.6464 | AG18: =9.72%*AC18 -> 110.64604 | AH18: =IF(OR(D18="SI", C18="SNP"), 0, VLOOKUP(C18, tbl_descuentos[], 2, FALSE) * SUM(Y18:AB18)) -> 0 | AI18: 0 | AJ18: =IF(OR(D18="SI", C18="SNP"), 0, VLOOKUP(C18, tbl_descuentos[], IF(E18 > 65, 4, 3), FALSE) * SUM(Y18:AB18)) -> 15.595172 | AK18: =IF(D18="SI",0,IF(C18="SNP",13%*SUM(Y18:AB18),0)) -> 0 | AL18: =IF(C18="SNP",0,IF(D18="SI",0,10%*(AC18+Y18))) -> 113.83337 | AM18: =SUMPRODUCT(ROUND(Y18:AB18, 2)) + SUMPRODUCT(ROUND(AD18:AG18, 2)) - SUMPRODUCT(ROUND(AH18:AL18, 2)) -> 1659.58 | AN18: =PROYECTADA!P18 -> 8.680434 | AO18: =6%*SUM(Y18:AB18) -> 68.300022 | AP18: =PROYECTADA!Q18 -> 7.853726 | AQ18: =PROYECTADA!R18 -> 7.5781567 | AS18: 1659.58 | AT18: 8.680434 | AU18: 68.300022 | AV18: 7.853726 | AW18: 7.5781567 | AX18: =IF(AND(AM18=AS18,AN18,AT18,AO18,AU18,AP18,AV18,AQ18,AW18),"OK","ERROR") -> OK
A19: 13 | B19: Parari Laura Teresa Lucy | C19: PRO M | V19: =SUM(L19:Q19) -> 0 | W19: =$AP$3-V19 -> 31 | X19: ='REPORTE DIARIO'!AI19 -> 216 | Y19: =PROYECTADA!G19 -> 0 | Z19: =1130/30*Q19 -> 0 | AA19: =PROYECTADA!D19/$AP$1*PLAME!X19 -> 1167.6667 | AB19: =PROYECTADA!F19/$AP$3*($AP$3-L19) -> 0 | AC19: =SUM(Z19:AB19) -> 1167.6667 | AD19: =6%*AF19 -> 11.671996 | AE19: =((30%*1130)/$AP$3)*($AP$3-L19) -> 339 | AF19: =16.66%*AC19 -> 194.53327 | AG19: =9.72%*AC19 -> 113.4972 | AH19: =IF(OR(D19="SI", C19="SNP"), 0, VLOOKUP(C19, tbl_descuentos[], 2, FALSE) * SUM(Y19:AB19)) -> 0 | AI19: 0 | AJ19: =IF(OR(D19="SI", C19="SNP"), 0, VLOOKUP(C19, tbl_descuentos[], IF(E19 > 65, 4, 3), FALSE) * SUM(Y19:AB19)) -> 15.997033 | AK19: =IF(D19="SI",0,IF(C19="SNP",13%*SUM(Y19:AB19),0)) -> 0 | AL19: =IF(C19="SNP",0,IF(D19="SI",0,10%*(AC19+Y19))) -> 116.76667 | AM19: =SUMPRODUCT(ROUND(Y19:AB19, 2)) + SUMPRODUCT(ROUND(AD19:AG19, 2)) - SUMPRODUCT(ROUND(AH19:AL19, 2)) -> 1693.6 | AN19: =PROYECTADA!P19 -> 8.680434 | AO19: =6%*SUM(Y19:AB19) -> 70.06 | AP19: =PROYECTADA!Q19 -> 7.853726 | AQ19: =PROYECTADA!R19 -> 7.5781567 | AX19: =IF(AND(AM19=AS19,AN19,AT19,AO19,AU19,AP19,AV19,AQ19,AW19),"OK","ERROR") -> ERROR
A20: 14 | B20: Pelinco Machaca, Monica | C20: PRI M | V20: =SUM(L20:Q20) -> 0 | W20: =$AP$3-V20 -> 31 | X20: ='REPORTE DIARIO'!AI20 -> 216 | Y20: =PROYECTADA!G20 -> 0 | Z20: =1130/30*Q20 -> 0 | AA20: =PROYECTADA!D20/$AP$1*PLAME!X20 -> 1167.6667 | AB20: =PROYECTADA!F20/$AP$3*($AP$3-L20) -> 0 | AC20: =SUM(Z20:AB20) -> 1167.6667 | AD20: =6%*AF20 -> 11.671996 | AE20: =((30%*1130)/$AP$3)*($AP$3-L20) -> 339 | AF20: =16.66%*AC20 -> 194.53327 | AG20: =9.72%*AC20 -> 113.4972 | AH20: =IF(OR(D20="SI", C20="SNP"), 0, VLOOKUP(C20, tbl_descuentos[], 2, FALSE) * SUM(Y20:AB20)) -> 0 | AI20: 0 | AJ20: =IF(OR(D20="SI", C20="SNP"), 0, VLOOKUP(C20, tbl_descuentos[], IF(E20 > 65, 4, 3), FALSE) * SUM(Y20:AB20)) -> 15.997033 | AK20: =IF(D20="SI",0,IF(C20="SNP",13%*SUM(Y20:AB20),0)) -> 0 | AL20: =IF(C20="SNP",0,IF(D20="SI",0,10%*(AC20+Y20))) -> 116.76667 | AM20: =SUMPRODUCT(ROUND(Y20:AB20, 2)) + SUMPRODUCT(ROUND(AD20:AG20, 2)) - SUMPRODUCT(ROUND(AH20:AL20, 2)) -> 1693.6 | AN20: =PROYECTADA!P20 -> 8.680434 | AO20: =6%*SUM(Y20:AB20) -> 70.06 | AP20: =PROYECTADA!Q20 -> 7.853726 | AQ20: =PROYECTADA!R20 -> 7.5781567 | AX20: =IF(AND(AM20=AS20,AN20,AT20,AO20,AU20,AP20,AV20,AQ20,AW20),"OK","ERROR") -> ERROR
A21: 15 | B21: Quispe Pacco Obita | C21: PRO F | V21: =SUM(L21:Q21) -> 0 | W21: =$AP$3-V21 -> 31 | X21: ='REPORTE DIARIO'!AI21 -> 216 | Y21: =PROYECTADA!G21 -> 0 | Z21: =1130/30*Q21 -> 0 | AA21: =PROYECTADA!D21/$AP$1*PLAME!X21 -> 1167.6667 | AB21: =PROYECTADA!F21/$AP$3*($AP$3-L21) -> 0 | AC21: =SUM(Z21:AB21) -> 1167.6667 | AD21: =6%*AF21 -> 11.671996 | AE21: =((30%*1130)/$AP$3)*($AP$3-L21) -> 339 | AF21: =16.66%*AC21 -> 194.53327 | AG21: =9.72%*AC21 -> 113.4972 | AH21: =IF(OR(D21="SI", C21="SNP"), 0, VLOOKUP(C21, tbl_descuentos[], 2, FALSE) * SUM(Y21:AB21)) -> 19.733567 | AI21: 0 | AJ21: =IF(OR(D21="SI", C21="SNP"), 0, VLOOKUP(C21, tbl_descuentos[], IF(E21 > 65, 4, 3), FALSE) * SUM(Y21:AB21)) -> 15.997033 | AK21: =IF(D21="SI",0,IF(C21="SNP",13%*SUM(Y21:AB21),0)) -> 0 | AL21: =IF(C21="SNP",0,IF(D21="SI",0,10%*(AC21+Y21))) -> 116.76667 | AM21: =SUMPRODUCT(ROUND(Y21:AB21, 2)) + SUMPRODUCT(ROUND(AD21:AG21, 2)) - SUMPRODUCT(ROUND(AH21:AL21, 2)) -> 1673.87 | AN21: =PROYECTADA!P21 -> 8.680434 | AO21: =6%*SUM(Y21:AB21) -> 70.06 | AP21: =PROYECTADA!Q21 -> 7.853726 | AQ21: =PROYECTADA!R21 -> 7.5781567 | AX21: =IF(AND(AM21=AS21,AN21,AT21,AO21,AU21,AP21,AV21,AQ21,AW21),"OK","ERROR") -> ERROR
A22: 16 | B22: Aragon Hancco Delia Jesusa | C22: INT M | V22: =SUM(L22:Q22) -> 0 | W22: =$AP$3-V22 -> 31 | X22: ='REPORTE DIARIO'!AI22 -> 189 | Y22: =PROYECTADA!G22 -> 103.58 | Z22: =1130/30*Q22 -> 0 | AA22: =PROYECTADA!D22/$AP$1*PLAME!X22 -> 1021.7083 | AB22: =PROYECTADA!F22/$AP$3*($AP$3-L22) -> 113 | AC22: =SUM(Z22:AB22) -> 1134.7083 | AD22: =6%*AF22 -> 11.342545 | AE22: =((30%*1130)/$AP$3)*($AP$3-L22) -> 339 | AF22: =16.66%*AC22 -> 189.04241 | AG22: =9.72%*AC22 -> 110.29365 | AH22: =IF(OR(D22="SI", C22="SNP"), 0, VLOOKUP(C22, tbl_descuentos[], 2, FALSE) * SUM(Y22:AB22)) -> 0 | AI22: 0 | AJ22: =IF(OR(D22="SI", C22="SNP"), 0, VLOOKUP(C22, tbl_descuentos[], IF(E22 > 65, 4, 3), FALSE) * SUM(Y22:AB22)) -> 16.96455 | AK22: =IF(D22="SI",0,IF(C22="SNP",13%*SUM(Y22:AB22),0)) -> 0 | AL22: =IF(C22="SNP",0,IF(D22="SI",0,10%*(AC22+Y22))) -> 123.82883 | AM22: =SUMPRODUCT(ROUND(Y22:AB22, 2)) + SUMPRODUCT(ROUND(AD22:AG22, 2)) - SUMPRODUCT(ROUND(AH22:AL22, 2)) -> 1747.17 | AN22: =PROYECTADA!P22 -> 10.29049 | AO22: =6%*SUM(Y22:AB22) -> 74.2973 | AP22: =PROYECTADA!Q22 -> 9.3104431 | AQ22: =PROYECTADA!R22 -> 8.9837609 | AX22: =IF(AND(AM22=AS22,AN22,AT22,AO22,AU22,AP22,AV22,AQ22,AW22),"OK","ERROR") -> ERROR
A23: 17 | B23: Gonzales Aparicio Lisbeth | C23: INT M | V23: =SUM(L23:Q23) -> 0 | W23: =$AP$3-V23 -> 31 | X23: ='REPORTE DIARIO'!AI23 -> 216 | Y23: =PROYECTADA!G23 -> 94.16 | Z23: =1130/30*Q23 -> 0 | AA23: =PROYECTADA!D23/$AP$1*PLAME!X23 -> 1167.6667 | AB23: =PROYECTADA!F23/$AP$3*($AP$3-L23) -> 0 | AC23: =SUM(Z23:AB23) -> 1167.6667 | AD23: =6%*AF23 -> 11.671996 | AE23: =((30%*1130)/$AP$3)*($AP$3-L23) -> 339 | AF23: =16.66%*AC23 -> 194.53327 | AG23: =9.72%*AC23 -> 113.4972 | AH23: =IF(OR(D23="SI", C23="SNP"), 0, VLOOKUP(C23, tbl_descuentos[], 2, FALSE) * SUM(Y23:AB23)) -> 0 | AI23: 0 | AJ23: =IF(OR(D23="SI", C23="SNP"), 0, VLOOKUP(C23, tbl_descuentos[], IF(E23 > 65, 4, 3), FALSE) * SUM(Y23:AB23)) -> 17.287025 | AK23: =IF(D23="SI",0,IF(C23="SNP",13%*SUM(Y23:AB23),0)) -> 0 | AL23: =IF(C23="SNP",0,IF(D23="SI",0,10%*(AC23+Y23))) -> 126.18267 | AM23: =SUMPRODUCT(ROUND(Y23:AB23, 2)) + SUMPRODUCT(ROUND(AD23:AG23, 2)) - SUMPRODUCT(ROUND(AH23:AL23, 2)) -> 1777.06 | AN23: =PROYECTADA!P23 -> 9.3804194 | AO23: =6%*SUM(Y23:AB23) -> 75.7096 | AP23: =PROYECTADA!Q23 -> 8.4870462 | AQ23: =PROYECTADA!R23 -> 8.1892551 | AX23: =IF(AND(AM23=AS23,AN23,AT23,AO23,AU23,AP23,AV23,AQ23,AW23),"OK","ERROR") -> ERROR
A24: 18 | B24: Sánchez Huanca María Luisa | C24: PRO M | V24: =SUM(L24:Q24) -> 0 | W24: =$AP$3-V24 -> 31 | X24: ='REPORTE DIARIO'!AI24 -> 216 | Y24: =PROYECTADA!G24 -> 103.58 | Z24: =1130/30*Q24 -> 0 | AA24: =PROYECTADA!D24/$AP$1*PLAME!X24 -> 1167.6667 | AB24: =PROYECTADA!F24/$AP$3*($AP$3-L24) -> 113 | AC24: =SUM(Z24:AB24) -> 1280.6667 | AD24: =6%*AF24 -> 12.801544 | AE24: =((30%*1130)/$AP$3)*($AP$3-L24) -> 339 | AF24: =16.66%*AC24 -> 213.35907 | AG24: =9.72%*AC24 -> 124.4808 | AH24: =IF(OR(D24="SI", C24="SNP"), 0, VLOOKUP(C24, tbl_descuentos[], 2, FALSE) * SUM(Y24:AB24)) -> 0 | AI24: 0 | AJ24: =IF(OR(D24="SI", C24="SNP"), 0, VLOOKUP(C24, tbl_descuentos[], IF(E24 > 65, 4, 3), FALSE) * SUM(Y24:AB24)) -> 18.964179 | AK24: =IF(D24="SI",0,IF(C24="SNP",13%*SUM(Y24:AB24),0)) -> 0 | AL24: =IF(C24="SNP",0,IF(D24="SI",0,10%*(AC24+Y24))) -> 138.42467 | AM24: =SUMPRODUCT(ROUND(Y24:AB24, 2)) + SUMPRODUCT(ROUND(AD24:AG24, 2)) - SUMPRODUCT(ROUND(AH24:AL24, 2)) -> 1916.51 | AN24: =PROYECTADA!P24 -> 10.29049 | AO24: =6%*SUM(Y24:AB24) -> 83.0548 | AP24: =PROYECTADA!Q24 -> 9.3104431 | AQ24: =PROYECTADA!R24 -> 8.9837609 | AX24: =IF(AND(AM24=AS24,AN24,AT24,AO24,AU24,AP24,AV24,AQ24,AW24),"OK","ERROR") -> ERROR
A25: 19 | B25: Alvarez Chavez, Richard | C25: PRO F | V25: =SUM(L25:Q25) -> 0 | W25: =$AP$3-V25 -> 31 | X25: ='REPORTE DIARIO'!AI25 -> 208 | Y25: =PROYECTADA!G25 -> 0 | Z25: =1130/30*Q25 -> 0 | AA25: =PROYECTADA!D25/$AP$1*PLAME!X25 -> 1124.4198 | AB25: =PROYECTADA!F25/$AP$3*($AP$3-L25) -> 113 | AC25: =SUM(Z25:AB25) -> 1237.4198 | AD25: =6%*AF25 -> 12.369248 | AE25: =((30%*1130)/$AP$3)*($AP$3-L25) -> 339 | AF25: =16.66%*AC25 -> 206.15413 | AG25: =9.72%*AC25 -> 120.2772 | AH25: =IF(OR(D25="SI", C25="SNP"), 0, VLOOKUP(C25, tbl_descuentos[], 2, FALSE) * SUM(Y25:AB25)) -> 20.912394 | AI25: 0 | AJ25: =IF(OR(D25="SI", C25="SNP"), 0, VLOOKUP(C25, tbl_descuentos[], IF(E25 > 65, 4, 3), FALSE) * SUM(Y25:AB25)) -> 16.952651 | AK25: =IF(D25="SI",0,IF(C25="SNP",13%*SUM(Y25:AB25),0)) -> 0 | AL25: =IF(C25="SNP",0,IF(D25="SI",0,10%*(AC25+Y25))) -> 123.74198 | AM25: =SUMPRODUCT(ROUND(Y25:AB25, 2)) + SUMPRODUCT(ROUND(AD25:AG25, 2)) - SUMPRODUCT(ROUND(AH25:AL25, 2)) -> 1753.62 | AN25: =PROYECTADA!P25 -> 9.520476 | AO25: =6%*SUM(Y25:AB25) -> 74.245185 | AP25: =PROYECTADA!Q25 -> 8.613764 | AQ25: =PROYECTADA!R25 -> 8.3115267 | AX25: =IF(AND(AM25=AS25,AN25,AT25,AO25,AU25,AP25,AV25,AQ25,AW25),"OK","ERROR") -> ERROR
A26: 20 | B26: Aparicio Ch Claver | C26: PRO F | V26: =SUM(L26:Q26) -> 0 | W26: =$AP$3-V26 -> 31 | X26: ='REPORTE DIARIO'!AI26 -> 216 | Y26: =PROYECTADA!G26 -> 0 | Z26: =1130/30*Q26 -> 0 | AA26: =PROYECTADA!D26/$AP$1*PLAME!X26 -> 1167.6667 | AB26: =PROYECTADA!F26/$AP$3*($AP$3-L26) -> 113 | AC26: =SUM(Z26:AB26) -> 1280.6667 | AD26: =6%*AF26 -> 12.801544 | AE26: =((30%*1130)/$AP$3)*($AP$3-L26) -> 339 | AF26: =16.66%*AC26 -> 213.35907 | AG26: =9.72%*AC26 -> 124.4808 | AH26: =IF(OR(D26="SI", C26="SNP"), 0, VLOOKUP(C26, tbl_descuentos[], 2, FALSE) * SUM(Y26:AB26)) -> 21.643267 | AI26: 0 | AJ26: =IF(OR(D26="SI", C26="SNP"), 0, VLOOKUP(C26, tbl_descuentos[], IF(E26 > 65, 4, 3), FALSE) * SUM(Y26:AB26)) -> 17.545133 | AK26: =IF(D26="SI",0,IF(C26="SNP",13%*SUM(Y26:AB26),0)) -> 0 | AL26: =IF(C26="SNP",0,IF(D26="SI",0,10%*(AC26+Y26))) -> 128.06667 | AM26: =SUMPRODUCT(ROUND(Y26:AB26, 2)) + SUMPRODUCT(ROUND(AD26:AG26, 2)) - SUMPRODUCT(ROUND(AH26:AL26, 2)) -> 1803.05 | AN26: =PROYECTADA!P26 -> 9.520476 | AO26: =6%*SUM(Y26:AB26) -> 76.84 | AP26: =PROYECTADA!Q26 -> 8.613764 | AQ26: =PROYECTADA!R26 -> 8.3115267 | AX26: =IF(AND(AM26=AS26,AN26,AT26,AO26,AU26,AP26,AV26,AQ26,AW26),"OK","ERROR") -> ERROR
A27: 21 | B27: Aquino Gomez Carmelo | C27: PRO F | V27: =SUM(L27:Q27) -> 0 | W27: =$AP$3-V27 -> 31 | X27: ='REPORTE DIARIO'!AI27 -> 216 | Y27: =PROYECTADA!G27 -> 0 | Z27: =1130/30*Q27 -> 0 | AA27: =PROYECTADA!D27/$AP$1*PLAME!X27 -> 1167.6667 | AB27: =PROYECTADA!F27/$AP$3*($AP$3-L27) -> 113 | AC27: =SUM(Z27:AB27) -> 1280.6667 | AD27: =6%*AF27 -> 12.801544 | AE27: =((30%*1130)/$AP$3)*($AP$3-L27) -> 339 | AF27: =16.66%*AC27 -> 213.35907 | AG27: =9.72%*AC27 -> 124.4808 | AH27: =IF(OR(D27="SI", C27="SNP"), 0, VLOOKUP(C27, tbl_descuentos[], 2, FALSE) * SUM(Y27:AB27)) -> 21.643267 | AI27: 0 | AJ27: =IF(OR(D27="SI", C27="SNP"), 0, VLOOKUP(C27, tbl_descuentos[], IF(E27 > 65, 4, 3), FALSE) * SUM(Y27:AB27)) -> 17.545133 | AK27: =IF(D27="SI",0,IF(C27="SNP",13%*SUM(Y27:AB27),0)) -> 0 | AL27: =IF(C27="SNP",0,IF(D27="SI",0,10%*(AC27+Y27))) -> 128.06667 | AM27: =SUMPRODUCT(ROUND(Y27:AB27, 2)) + SUMPRODUCT(ROUND(AD27:AG27, 2)) - SUMPRODUCT(ROUND(AH27:AL27, 2)) -> 1803.05 | AN27: =PROYECTADA!P27 -> 9.520476 | AO27: =6%*SUM(Y27:AB27) -> 76.84 | AP27: =PROYECTADA!Q27 -> 8.613764 | AQ27: =PROYECTADA!R27 -> 8.3115267 | AX27: =IF(AND(AM27=AS27,AN27,AT27,AO27,AU27,AP27,AV27,AQ27,AW27),"OK","ERROR") -> ERROR
A28: 22 | B28: Ayamamani Chura Elver Emilio | C28: PRO F | V28: =SUM(F28:U28) -> 0 | W28: =$AP$3-V28 -> 31 | X28: ='REPORTE DIARIO'!AI28 -> 216 | Y28: =PROYECTADA!G28 -> 0 | Z28: =1130/30*Q28 -> 0 | AA28: =PROYECTADA!D28/$AP$1*PLAME!X28 -> 1167.6667 | AB28: =PROYECTADA!F28/$AP$3*($AP$3-L28) -> 113 | AC28: =SUM(Z28:AB28) -> 1280.6667 | AD28: =6%*AF28 -> 12.801544 | AE28: =((30%*1130)/$AP$3)*($AP$3-L28) -> 339 | AF28: =16.66%*AC28 -> 213.35907 | AG28: =9.72%*AC28 -> 124.4808 | AH28: =IF(OR(D28="SI", C28="SNP"), 0, VLOOKUP(C28, tbl_descuentos[], 2, FALSE) * SUM(Y28:AB28)) -> 21.643267 | AI28: 0 | AJ28: =IF(OR(D28="SI", C28="SNP"), 0, VLOOKUP(C28, tbl_descuentos[], IF(E28 > 65, 4, 3), FALSE) * SUM(Y28:AB28)) -> 17.545133 | AK28: =IF(D28="SI",0,IF(C28="SNP",13%*SUM(Y28:AB28),0)) -> 0 | AL28: =IF(C28="SNP",0,IF(D28="SI",0,10%*(AC28+Y28))) -> 128.06667 | AM28: =SUMPRODUCT(ROUND(Y28:AB28, 2)) + SUMPRODUCT(ROUND(AD28:AG28, 2)) - SUMPRODUCT(ROUND(AH28:AL28, 2)) -> 1803.05 | AN28: =PROYECTADA!P28 -> 9.7269182 | AO28: =6%*SUM(Y28:AB28) -> 76.84 | AP28: =PROYECTADA!Q28 -> 8.800545 | AQ28: =PROYECTADA!R28 -> 8.491754 | AX28: =IF(AND(AM28=AS28,AN28,AT28,AO28,AU28,AP28,AV28,AQ28,AW28),"OK","ERROR") -> ERROR
